Internal Server Error: /admin/accounts/account/1/change/
Traceback (most recent call last):
  File "C:\ProgramData\anaconda3\envs\django\Lib\site-packages\django\contrib\admin\options.py", line 809, in get_form
    return modelform_factory(self.model, **defaults)
           ^^^^^^^^^^^^^^^^^^^^^^^^^^^^^^^^^^^^^^^^^
  File "C:\ProgramData\anaconda3\envs\django\Lib\site-packages\django\forms\models.py", line 642, in modelform_factory
    return type(form)(class_name, (form,), form_class_attrs)
           ^^^^^^^^^^^^^^^^^^^^^^^^^^^^^^^^^^^^^^^^^^^^^^^^^
  File "C:\ProgramData\anaconda3\envs\django\Lib\site-packages\django\forms\models.py", line 321, in __new__
    raise FieldError(message)
django.core.exceptions.FieldError: Unknown field(s) (research_group) specified for Account

During handling of the above exception, another exception occurred:

Traceback (most recent call last):
  File "C:\ProgramData\anaconda3\envs\django\Lib\site-packages\django\core\handlers\exception.py", line 55, in inner
    response = get_response(request)
               ^^^^^^^^^^^^^^^^^^^^^
  File "C:\ProgramData\anaconda3\envs\django\Lib\site-packages\django\core\handlers\base.py", line 197, in _get_response
    response = wrapped_callback(request, *callback_args, **callback_kwargs)
               ^^^^^^^^^^^^^^^^^^^^^^^^^^^^^^^^^^^^^^^^^^^^^^^^^^^^^^^^^^^^
  File "C:\ProgramData\anaconda3\envs\django\Lib\site-packages\django\contrib\admin\options.py", line 688, in wrapper
    return self.admin_site.admin_view(view)(*args, **kwargs)
           ^^^^^^^^^^^^^^^^^^^^^^^^^^^^^^^^^^^^^^^^^^^^^^^^^
  File "C:\ProgramData\anaconda3\envs\django\Lib\site-packages\django\utils\decorators.py", line 134, in _wrapper_view
    response = view_func(request, *args, **kwargs)
               ^^^^^^^^^^^^^^^^^^^^^^^^^^^^^^^^^^^
  File "C:\ProgramData\anaconda3\envs\django\Lib\site-packages\django\views\decorators\cache.py", line 62, in _wrapper_view_func
    response = view_func(request, *args, **kwargs)
               ^^^^^^^^^^^^^^^^^^^^^^^^^^^^^^^^^^^
  File "C:\ProgramData\anaconda3\envs\django\Lib\site-packages\django\contrib\admin\sites.py", line 242, in inner
    return view(request, *args, **kwargs)
           ^^^^^^^^^^^^^^^^^^^^^^^^^^^^^^
  File "C:\ProgramData\anaconda3\envs\django\Lib\site-packages\django\contrib\admin\options.py", line 1889, in change_view
    return self.changeform_view(request, object_id, form_url, extra_context)
           ^^^^^^^^^^^^^^^^^^^^^^^^^^^^^^^^^^^^^^^^^^^^^^^^^^^^^^^^^^^^^^^^^
  File "C:\ProgramData\anaconda3\envs\django\Lib\site-packages\django\utils\decorators.py", line 46, in _wrapper
    return bound_method(*args, **kwargs)
           ^^^^^^^^^^^^^^^^^^^^^^^^^^^^^
  File "C:\ProgramData\anaconda3\envs\django\Lib\site-packages\django\utils\decorators.py", line 134, in _wrapper_view
    response = view_func(request, *args, **kwargs)
               ^^^^^^^^^^^^^^^^^^^^^^^^^^^^^^^^^^^
  File "C:\ProgramData\anaconda3\envs\django\Lib\site-packages\django\contrib\admin\options.py", line 1747, in changeform_view
    return self._changeform_view(request, object_id, form_url, extra_context)
           ^^^^^^^^^^^^^^^^^^^^^^^^^^^^^^^^^^^^^^^^^^^^^^^^^^^^^^^^^^^^^^^^^^
  File "C:\ProgramData\anaconda3\envs\django\Lib\site-packages\django\contrib\admin\options.py", line 1782, in _changeform_view
    ModelForm = self.get_form(
                ^^^^^^^^^^^^^^
  File "C:\ProgramData\anaconda3\envs\django\Lib\site-packages\django\contrib\admin\options.py", line 811, in get_form
    raise FieldError(
django.core.exceptions.FieldError: Unknown field(s) (research_group) specified for Account. Check fields/fieldsets/exclude attributes of class AccountrAdmin.
Internal Server Error: /
Traceback (most recent call last):
  File "C:\ProgramData\anaconda3\envs\django\Lib\site-packages\django\core\handlers\exception.py", line 55, in inner
    response = get_response(request)
               ^^^^^^^^^^^^^^^^^^^^^
  File "C:\ProgramData\anaconda3\envs\django\Lib\site-packages\django\core\handlers\base.py", line 197, in _get_response
    response = wrapped_callback(request, *callback_args, **callback_kwargs)
               ^^^^^^^^^^^^^^^^^^^^^^^^^^^^^^^^^^^^^^^^^^^^^^^^^^^^^^^^^^^^
  File "C:\ProgramData\anaconda3\envs\django\Lib\site-packages\django\views\decorators\csrf.py", line 56, in wrapper_view
    return view_func(*args, **kwargs)
           ^^^^^^^^^^^^^^^^^^^^^^^^^^
  File "C:\ProgramData\anaconda3\envs\django\Lib\site-packages\django\views\generic\base.py", line 104, in view
    return self.dispatch(request, *args, **kwargs)
           ^^^^^^^^^^^^^^^^^^^^^^^^^^^^^^^^^^^^^^^
  File "C:\ProgramData\anaconda3\envs\django\Lib\site-packages\rest_framework\views.py", line 509, in dispatch
    response = self.handle_exception(exc)
               ^^^^^^^^^^^^^^^^^^^^^^^^^^
  File "C:\ProgramData\anaconda3\envs\django\Lib\site-packages\rest_framework\views.py", line 469, in handle_exception
    self.raise_uncaught_exception(exc)
  File "C:\ProgramData\anaconda3\envs\django\Lib\site-packages\rest_framework\views.py", line 480, in raise_uncaught_exception
    raise exc
  File "C:\ProgramData\anaconda3\envs\django\Lib\site-packages\rest_framework\views.py", line 497, in dispatch
    self.initial(request, *args, **kwargs)
  File "C:\ProgramData\anaconda3\envs\django\Lib\site-packages\rest_framework\views.py", line 415, in initial
    self.check_permissions(request)
  File "C:\ProgramData\anaconda3\envs\django\Lib\site-packages\rest_framework\views.py", line 332, in check_permissions
    if not permission.has_permission(request, self):
           ^^^^^^^^^^^^^^^^^^^^^^^^^
AttributeError: 'SessionAuthentication' object has no attribute 'has_permission'
Internal Server Error: /
Traceback (most recent call last):
  File "C:\ProgramData\anaconda3\envs\django\Lib\site-packages\django\core\handlers\exception.py", line 55, in inner
    response = get_response(request)
               ^^^^^^^^^^^^^^^^^^^^^
  File "C:\ProgramData\anaconda3\envs\django\Lib\site-packages\django\core\handlers\base.py", line 197, in _get_response
    response = wrapped_callback(request, *callback_args, **callback_kwargs)
               ^^^^^^^^^^^^^^^^^^^^^^^^^^^^^^^^^^^^^^^^^^^^^^^^^^^^^^^^^^^^
  File "C:\ProgramData\anaconda3\envs\django\Lib\site-packages\django\views\decorators\csrf.py", line 56, in wrapper_view
    return view_func(*args, **kwargs)
           ^^^^^^^^^^^^^^^^^^^^^^^^^^
  File "C:\ProgramData\anaconda3\envs\django\Lib\site-packages\django\views\generic\base.py", line 104, in view
    return self.dispatch(request, *args, **kwargs)
           ^^^^^^^^^^^^^^^^^^^^^^^^^^^^^^^^^^^^^^^
  File "C:\ProgramData\anaconda3\envs\django\Lib\site-packages\rest_framework\views.py", line 509, in dispatch
    response = self.handle_exception(exc)
               ^^^^^^^^^^^^^^^^^^^^^^^^^^
  File "C:\ProgramData\anaconda3\envs\django\Lib\site-packages\rest_framework\views.py", line 469, in handle_exception
    self.raise_uncaught_exception(exc)
  File "C:\ProgramData\anaconda3\envs\django\Lib\site-packages\rest_framework\views.py", line 480, in raise_uncaught_exception
    raise exc
  File "C:\ProgramData\anaconda3\envs\django\Lib\site-packages\rest_framework\views.py", line 497, in dispatch
    self.initial(request, *args, **kwargs)
  File "C:\ProgramData\anaconda3\envs\django\Lib\site-packages\rest_framework\views.py", line 415, in initial
    self.check_permissions(request)
  File "C:\ProgramData\anaconda3\envs\django\Lib\site-packages\rest_framework\views.py", line 332, in check_permissions
    if not permission.has_permission(request, self):
           ^^^^^^^^^^^^^^^^^^^^^^^^^
AttributeError: 'BasicAuthentication' object has no attribute 'has_permission'
Internal Server Error: /api/groups/
Traceback (most recent call last):
  File "C:\ProgramData\anaconda3\envs\django\Lib\site-packages\django\core\handlers\exception.py", line 55, in inner
    response = get_response(request)
               ^^^^^^^^^^^^^^^^^^^^^
  File "C:\ProgramData\anaconda3\envs\django\Lib\site-packages\django\core\handlers\base.py", line 197, in _get_response
    response = wrapped_callback(request, *callback_args, **callback_kwargs)
               ^^^^^^^^^^^^^^^^^^^^^^^^^^^^^^^^^^^^^^^^^^^^^^^^^^^^^^^^^^^^
  File "C:\ProgramData\anaconda3\envs\django\Lib\site-packages\django\views\decorators\csrf.py", line 56, in wrapper_view
    return view_func(*args, **kwargs)
           ^^^^^^^^^^^^^^^^^^^^^^^^^^
  File "C:\ProgramData\anaconda3\envs\django\Lib\site-packages\rest_framework\viewsets.py", line 125, in view
    return self.dispatch(request, *args, **kwargs)
           ^^^^^^^^^^^^^^^^^^^^^^^^^^^^^^^^^^^^^^^
  File "C:\ProgramData\anaconda3\envs\django\Lib\site-packages\rest_framework\views.py", line 509, in dispatch
    response = self.handle_exception(exc)
               ^^^^^^^^^^^^^^^^^^^^^^^^^^
  File "C:\ProgramData\anaconda3\envs\django\Lib\site-packages\rest_framework\views.py", line 469, in handle_exception
    self.raise_uncaught_exception(exc)
  File "C:\ProgramData\anaconda3\envs\django\Lib\site-packages\rest_framework\views.py", line 480, in raise_uncaught_exception
    raise exc
  File "C:\ProgramData\anaconda3\envs\django\Lib\site-packages\rest_framework\views.py", line 506, in dispatch
    response = handler(request, *args, **kwargs)
               ^^^^^^^^^^^^^^^^^^^^^^^^^^^^^^^^^
  File "C:\ProgramData\anaconda3\envs\django\Lib\site-packages\rest_framework\mixins.py", line 38, in list
    queryset = self.filter_queryset(self.get_queryset())
               ^^^^^^^^^^^^^^^^^^^^^^^^^^^^^^^^^^^^^^^^^
  File "C:\ProgramData\anaconda3\envs\django\Lib\site-packages\rest_framework\generics.py", line 150, in filter_queryset
    queryset = backend().filter_queryset(self.request, queryset, self)
               ^^^^^^^^^^^^^^^^^^^^^^^^^^^^^^^^^^^^^^^^^^^^^^^^^^^^^^^
  File "C:\ProgramData\anaconda3\envs\django\Lib\site-packages\django_filters\rest_framework\backends.py", line 68, in filter_queryset
    filterset = self.get_filterset(request, queryset, view)
                ^^^^^^^^^^^^^^^^^^^^^^^^^^^^^^^^^^^^^^^^^^^
  File "C:\ProgramData\anaconda3\envs\django\Lib\site-packages\django_filters\rest_framework\backends.py", line 20, in get_filterset
    filterset_class = self.get_filterset_class(view, queryset)
                      ^^^^^^^^^^^^^^^^^^^^^^^^^^^^^^^^^^^^^^^^
  File "C:\ProgramData\anaconda3\envs\django\Lib\site-packages\django_filters\rest_framework\backends.py", line 51, in get_filterset_class
    class AutoFilterSet(self.filterset_base):
  File "C:\ProgramData\anaconda3\envs\django\Lib\site-packages\django_filters\filterset.py", line 62, in __new__
    new_class.base_filters = new_class.get_filters()
                             ^^^^^^^^^^^^^^^^^^^^^^^
  File "C:\ProgramData\anaconda3\envs\django\Lib\site-packages\django_filters\filterset.py", line 349, in get_filters
    raise TypeError(
TypeError: 'Meta.fields' must not contain non-model field names: name__regex
Internal Server Error: /api/programmes/
Traceback (most recent call last):
  File "C:\ProgramData\anaconda3\envs\django\Lib\site-packages\django\core\handlers\exception.py", line 55, in inner
    response = get_response(request)
               ^^^^^^^^^^^^^^^^^^^^^
  File "C:\ProgramData\anaconda3\envs\django\Lib\site-packages\django\core\handlers\base.py", line 197, in _get_response
    response = wrapped_callback(request, *callback_args, **callback_kwargs)
               ^^^^^^^^^^^^^^^^^^^^^^^^^^^^^^^^^^^^^^^^^^^^^^^^^^^^^^^^^^^^
  File "C:\ProgramData\anaconda3\envs\django\Lib\site-packages\django\views\decorators\csrf.py", line 56, in wrapper_view
    return view_func(*args, **kwargs)
           ^^^^^^^^^^^^^^^^^^^^^^^^^^
  File "C:\ProgramData\anaconda3\envs\django\Lib\site-packages\rest_framework\viewsets.py", line 125, in view
    return self.dispatch(request, *args, **kwargs)
           ^^^^^^^^^^^^^^^^^^^^^^^^^^^^^^^^^^^^^^^
  File "C:\ProgramData\anaconda3\envs\django\Lib\site-packages\rest_framework\views.py", line 509, in dispatch
    response = self.handle_exception(exc)
               ^^^^^^^^^^^^^^^^^^^^^^^^^^
  File "C:\ProgramData\anaconda3\envs\django\Lib\site-packages\rest_framework\views.py", line 469, in handle_exception
    self.raise_uncaught_exception(exc)
  File "C:\ProgramData\anaconda3\envs\django\Lib\site-packages\rest_framework\views.py", line 480, in raise_uncaught_exception
    raise exc
  File "C:\ProgramData\anaconda3\envs\django\Lib\site-packages\rest_framework\views.py", line 506, in dispatch
    response = handler(request, *args, **kwargs)
               ^^^^^^^^^^^^^^^^^^^^^^^^^^^^^^^^^
  File "C:\ProgramData\anaconda3\envs\django\Lib\site-packages\rest_framework\mixins.py", line 38, in list
    queryset = self.filter_queryset(self.get_queryset())
               ^^^^^^^^^^^^^^^^^^^^^^^^^^^^^^^^^^^^^^^^^
  File "C:\ProgramData\anaconda3\envs\django\Lib\site-packages\rest_framework\generics.py", line 150, in filter_queryset
    queryset = backend().filter_queryset(self.request, queryset, self)
               ^^^^^^^^^^^^^^^^^^^^^^^^^^^^^^^^^^^^^^^^^^^^^^^^^^^^^^^
  File "C:\ProgramData\anaconda3\envs\django\Lib\site-packages\django_filters\rest_framework\backends.py", line 68, in filter_queryset
    filterset = self.get_filterset(request, queryset, view)
                ^^^^^^^^^^^^^^^^^^^^^^^^^^^^^^^^^^^^^^^^^^^
  File "C:\ProgramData\anaconda3\envs\django\Lib\site-packages\django_filters\rest_framework\backends.py", line 20, in get_filterset
    filterset_class = self.get_filterset_class(view, queryset)
                      ^^^^^^^^^^^^^^^^^^^^^^^^^^^^^^^^^^^^^^^^
  File "C:\ProgramData\anaconda3\envs\django\Lib\site-packages\django_filters\rest_framework\backends.py", line 51, in get_filterset_class
    class AutoFilterSet(self.filterset_base):
  File "C:\ProgramData\anaconda3\envs\django\Lib\site-packages\django_filters\filterset.py", line 62, in __new__
    new_class.base_filters = new_class.get_filters()
                             ^^^^^^^^^^^^^^^^^^^^^^^
  File "C:\ProgramData\anaconda3\envs\django\Lib\site-packages\django_filters\filterset.py", line 349, in get_filters
    raise TypeError(
TypeError: 'Meta.fields' must not contain non-model field names: code, level, local
Internal Server Error: /api/programmes/
Traceback (most recent call last):
  File "C:\ProgramData\anaconda3\envs\django\Lib\site-packages\django\core\handlers\exception.py", line 55, in inner
    response = get_response(request)
               ^^^^^^^^^^^^^^^^^^^^^
  File "C:\ProgramData\anaconda3\envs\django\Lib\site-packages\django\core\handlers\base.py", line 197, in _get_response
    response = wrapped_callback(request, *callback_args, **callback_kwargs)
               ^^^^^^^^^^^^^^^^^^^^^^^^^^^^^^^^^^^^^^^^^^^^^^^^^^^^^^^^^^^^
  File "C:\ProgramData\anaconda3\envs\django\Lib\site-packages\django\views\decorators\csrf.py", line 56, in wrapper_view
    return view_func(*args, **kwargs)
           ^^^^^^^^^^^^^^^^^^^^^^^^^^
  File "C:\ProgramData\anaconda3\envs\django\Lib\site-packages\rest_framework\viewsets.py", line 125, in view
    return self.dispatch(request, *args, **kwargs)
           ^^^^^^^^^^^^^^^^^^^^^^^^^^^^^^^^^^^^^^^
  File "C:\ProgramData\anaconda3\envs\django\Lib\site-packages\rest_framework\views.py", line 509, in dispatch
    response = self.handle_exception(exc)
               ^^^^^^^^^^^^^^^^^^^^^^^^^^
  File "C:\ProgramData\anaconda3\envs\django\Lib\site-packages\rest_framework\views.py", line 469, in handle_exception
    self.raise_uncaught_exception(exc)
  File "C:\ProgramData\anaconda3\envs\django\Lib\site-packages\rest_framework\views.py", line 480, in raise_uncaught_exception
    raise exc
  File "C:\ProgramData\anaconda3\envs\django\Lib\site-packages\rest_framework\views.py", line 506, in dispatch
    response = handler(request, *args, **kwargs)
               ^^^^^^^^^^^^^^^^^^^^^^^^^^^^^^^^^
  File "C:\ProgramData\anaconda3\envs\django\Lib\site-packages\rest_framework\mixins.py", line 38, in list
    queryset = self.filter_queryset(self.get_queryset())
               ^^^^^^^^^^^^^^^^^^^^^^^^^^^^^^^^^^^^^^^^^
  File "C:\ProgramData\anaconda3\envs\django\Lib\site-packages\rest_framework\generics.py", line 150, in filter_queryset
    queryset = backend().filter_queryset(self.request, queryset, self)
               ^^^^^^^^^^^^^^^^^^^^^^^^^^^^^^^^^^^^^^^^^^^^^^^^^^^^^^^
  File "C:\ProgramData\anaconda3\envs\django\Lib\site-packages\django_filters\rest_framework\backends.py", line 68, in filter_queryset
    filterset = self.get_filterset(request, queryset, view)
                ^^^^^^^^^^^^^^^^^^^^^^^^^^^^^^^^^^^^^^^^^^^
  File "C:\ProgramData\anaconda3\envs\django\Lib\site-packages\django_filters\rest_framework\backends.py", line 20, in get_filterset
    filterset_class = self.get_filterset_class(view, queryset)
                      ^^^^^^^^^^^^^^^^^^^^^^^^^^^^^^^^^^^^^^^^
  File "C:\ProgramData\anaconda3\envs\django\Lib\site-packages\django_filters\rest_framework\backends.py", line 51, in get_filterset_class
    class AutoFilterSet(self.filterset_base):
  File "C:\ProgramData\anaconda3\envs\django\Lib\site-packages\django_filters\filterset.py", line 62, in __new__
    new_class.base_filters = new_class.get_filters()
                             ^^^^^^^^^^^^^^^^^^^^^^^
  File "C:\ProgramData\anaconda3\envs\django\Lib\site-packages\django_filters\filterset.py", line 349, in get_filters
    raise TypeError(
TypeError: 'Meta.fields' must not contain non-model field names: code, level, local
Internal Server Error: /minerva/import_tests/
Traceback (most recent call last):
  File "C:\ProgramData\anaconda3\envs\django\Lib\site-packages\django\template\defaulttags.py", line 1026, in find_library
    return parser.libraries[name]
           ~~~~~~~~~~~~~~~~^^^^^^
KeyError: 'bootstrap5'

During handling of the above exception, another exception occurred:

Traceback (most recent call last):
  File "C:\ProgramData\anaconda3\envs\django\Lib\site-packages\django\core\handlers\exception.py", line 55, in inner
    response = get_response(request)
               ^^^^^^^^^^^^^^^^^^^^^
  File "C:\ProgramData\anaconda3\envs\django\Lib\site-packages\django\core\handlers\base.py", line 220, in _get_response
    response = response.render()
               ^^^^^^^^^^^^^^^^^
  File "C:\ProgramData\anaconda3\envs\django\Lib\site-packages\django\template\response.py", line 114, in render
    self.content = self.rendered_content
                   ^^^^^^^^^^^^^^^^^^^^^
  File "C:\ProgramData\anaconda3\envs\django\Lib\site-packages\django\template\response.py", line 90, in rendered_content
    template = self.resolve_template(self.template_name)
               ^^^^^^^^^^^^^^^^^^^^^^^^^^^^^^^^^^^^^^^^^
  File "C:\ProgramData\anaconda3\envs\django\Lib\site-packages\django\template\response.py", line 72, in resolve_template
    return select_template(template, using=self.using)
           ^^^^^^^^^^^^^^^^^^^^^^^^^^^^^^^^^^^^^^^^^^^
  File "C:\ProgramData\anaconda3\envs\django\Lib\site-packages\django\template\loader.py", line 42, in select_template
    return engine.get_template(template_name)
           ^^^^^^^^^^^^^^^^^^^^^^^^^^^^^^^^^^
  File "C:\ProgramData\anaconda3\envs\django\Lib\site-packages\django\template\backends\django.py", line 33, in get_template
    return Template(self.engine.get_template(template_name), self)
                    ^^^^^^^^^^^^^^^^^^^^^^^^^^^^^^^^^^^^^^^
  File "C:\ProgramData\anaconda3\envs\django\Lib\site-packages\django\template\engine.py", line 175, in get_template
    template, origin = self.find_template(template_name)
                       ^^^^^^^^^^^^^^^^^^^^^^^^^^^^^^^^^
  File "C:\ProgramData\anaconda3\envs\django\Lib\site-packages\django\template\engine.py", line 157, in find_template
    template = loader.get_template(name, skip=skip)
               ^^^^^^^^^^^^^^^^^^^^^^^^^^^^^^^^^^^^
  File "C:\ProgramData\anaconda3\envs\django\Lib\site-packages\django\template\loaders\cached.py", line 57, in get_template
    template = super().get_template(template_name, skip)
               ^^^^^^^^^^^^^^^^^^^^^^^^^^^^^^^^^^^^^^^^^
  File "C:\ProgramData\anaconda3\envs\django\Lib\site-packages\django\template\loaders\base.py", line 28, in get_template
    return Template(
           ^^^^^^^^^
  File "C:\ProgramData\anaconda3\envs\django\Lib\site-packages\django\template\base.py", line 154, in __init__
    self.nodelist = self.compile_nodelist()
                    ^^^^^^^^^^^^^^^^^^^^^^^
  File "C:\ProgramData\anaconda3\envs\django\Lib\site-packages\django\template\base.py", line 200, in compile_nodelist
    return parser.parse()
           ^^^^^^^^^^^^^^
  File "C:\ProgramData\anaconda3\envs\django\Lib\site-packages\django\template\base.py", line 513, in parse
    raise self.error(token, e)
  File "C:\ProgramData\anaconda3\envs\django\Lib\site-packages\django\template\base.py", line 511, in parse
    compiled_result = compile_func(self, token)
                      ^^^^^^^^^^^^^^^^^^^^^^^^^
  File "C:\ProgramData\anaconda3\envs\django\Lib\site-packages\django\template\loader_tags.py", line 293, in do_extends
    nodelist = parser.parse()
               ^^^^^^^^^^^^^^
  File "C:\ProgramData\anaconda3\envs\django\Lib\site-packages\django\template\base.py", line 513, in parse
    raise self.error(token, e)
  File "C:\ProgramData\anaconda3\envs\django\Lib\site-packages\django\template\base.py", line 511, in parse
    compiled_result = compile_func(self, token)
                      ^^^^^^^^^^^^^^^^^^^^^^^^^
  File "C:\ProgramData\anaconda3\envs\django\Lib\site-packages\django\template\defaulttags.py", line 1088, in load
    lib = find_library(parser, name)
          ^^^^^^^^^^^^^^^^^^^^^^^^^^
  File "C:\ProgramData\anaconda3\envs\django\Lib\site-packages\django\template\defaulttags.py", line 1028, in find_library
    raise TemplateSyntaxError(
django.template.exceptions.TemplateSyntaxError: 'bootstrap5' is not a registered tag library. Must be one of:
admin_list
admin_modify
admin_urls
baton_tags
cache
cookielaw_tags
debugger_tags
django_bootstrap5
django_tables2
email_obfuscator
flatpages
floppyforms
floppyforms_internals
highlighting
i18n
import_export_tags
indent_text
l10n
log
mathfilters
rest_framework
sitetree
static
syntax_color
tz
widont
Internal Server Error: /minerva/import_tests/
Traceback (most recent call last):
  File "C:\ProgramData\anaconda3\envs\django\Lib\site-packages\django\core\handlers\exception.py", line 55, in inner
    response = get_response(request)
               ^^^^^^^^^^^^^^^^^^^^^
  File "C:\ProgramData\anaconda3\envs\django\Lib\site-packages\django\core\handlers\base.py", line 197, in _get_response
    response = wrapped_callback(request, *callback_args, **callback_kwargs)
               ^^^^^^^^^^^^^^^^^^^^^^^^^^^^^^^^^^^^^^^^^^^^^^^^^^^^^^^^^^^^
  File "C:\ProgramData\anaconda3\envs\django\Lib\site-packages\django\views\generic\base.py", line 104, in view
    return self.dispatch(request, *args, **kwargs)
           ^^^^^^^^^^^^^^^^^^^^^^^^^^^^^^^^^^^^^^^
  File "C:\ProgramData\anaconda3\envs\django\Lib\site-packages\django\contrib\auth\mixins.py", line 135, in dispatch
    return super().dispatch(request, *args, **kwargs)
           ^^^^^^^^^^^^^^^^^^^^^^^^^^^^^^^^^^^^^^^^^^
  File "C:\ProgramData\anaconda3\envs\django\Lib\site-packages\django\views\generic\base.py", line 143, in dispatch
    return handler(request, *args, **kwargs)
           ^^^^^^^^^^^^^^^^^^^^^^^^^^^^^^^^^
  File "C:\ProgramData\anaconda3\envs\django\Lib\site-packages\django\views\generic\edit.py", line 144, in get
    return self.render_to_response(self.get_context_data())
                                   ^^^^^^^^^^^^^^^^^^^^^^^
  File "C:\ProgramData\anaconda3\envs\django\Lib\site-packages\django\views\generic\edit.py", line 74, in get_context_data
    kwargs["form"] = self.get_form()
                     ^^^^^^^^^^^^^^^
  File "C:\ProgramData\anaconda3\envs\django\Lib\site-packages\django\views\generic\edit.py", line 39, in get_form
    return form_class(**self.get_form_kwargs())
           ^^^^^^^^^^^^^^^^^^^^^^^^^^^^^^^^^^^^
  File "C:\Users\gavin\OneDrive - University of Leeds\Documents\Programming\phas_vitals\apps\minerva\forms.py", line 17, in __init__
    suer().__init__(*args, **kargs)
    ^^^^
NameError: name 'suer' is not defined
Internal Server Error: /minerva/import_tests/
Traceback (most recent call last):
  File "C:\ProgramData\anaconda3\envs\django\Lib\site-packages\django\core\handlers\exception.py", line 55, in inner
    response = get_response(request)
               ^^^^^^^^^^^^^^^^^^^^^
  File "C:\ProgramData\anaconda3\envs\django\Lib\site-packages\django\core\handlers\base.py", line 197, in _get_response
    response = wrapped_callback(request, *callback_args, **callback_kwargs)
               ^^^^^^^^^^^^^^^^^^^^^^^^^^^^^^^^^^^^^^^^^^^^^^^^^^^^^^^^^^^^
  File "C:\ProgramData\anaconda3\envs\django\Lib\site-packages\django\views\generic\base.py", line 104, in view
    return self.dispatch(request, *args, **kwargs)
           ^^^^^^^^^^^^^^^^^^^^^^^^^^^^^^^^^^^^^^^
  File "C:\ProgramData\anaconda3\envs\django\Lib\site-packages\django\contrib\auth\mixins.py", line 135, in dispatch
    return super().dispatch(request, *args, **kwargs)
           ^^^^^^^^^^^^^^^^^^^^^^^^^^^^^^^^^^^^^^^^^^
  File "C:\ProgramData\anaconda3\envs\django\Lib\site-packages\django\views\generic\base.py", line 143, in dispatch
    return handler(request, *args, **kwargs)
           ^^^^^^^^^^^^^^^^^^^^^^^^^^^^^^^^^
  File "C:\ProgramData\anaconda3\envs\django\Lib\site-packages\django\views\generic\edit.py", line 144, in get
    return self.render_to_response(self.get_context_data())
                                   ^^^^^^^^^^^^^^^^^^^^^^^
  File "C:\ProgramData\anaconda3\envs\django\Lib\site-packages\django\views\generic\edit.py", line 74, in get_context_data
    kwargs["form"] = self.get_form()
                     ^^^^^^^^^^^^^^^
  File "C:\ProgramData\anaconda3\envs\django\Lib\site-packages\django\views\generic\edit.py", line 39, in get_form
    return form_class(**self.get_form_kwargs())
           ^^^^^^^^^^^^^^^^^^^^^^^^^^^^^^^^^^^^
  File "C:\Users\gavin\OneDrive - University of Leeds\Documents\Programming\phas_vitals\apps\minerva\forms.py", line 19, in __init__
    assert False
AssertionError
Internal Server Error: /minerva/import_tests/
Traceback (most recent call last):
  File "C:\ProgramData\anaconda3\envs\django\Lib\site-packages\django\template\base.py", line 505, in parse
    compile_func = self.tags[command]
                   ~~~~~~~~~^^^^^^^^^
KeyError: 'buttons'

During handling of the above exception, another exception occurred:

Traceback (most recent call last):
  File "C:\ProgramData\anaconda3\envs\django\Lib\site-packages\django\core\handlers\exception.py", line 55, in inner
    response = get_response(request)
               ^^^^^^^^^^^^^^^^^^^^^
  File "C:\ProgramData\anaconda3\envs\django\Lib\site-packages\django\core\handlers\base.py", line 220, in _get_response
    response = response.render()
               ^^^^^^^^^^^^^^^^^
  File "C:\ProgramData\anaconda3\envs\django\Lib\site-packages\django\template\response.py", line 114, in render
    self.content = self.rendered_content
                   ^^^^^^^^^^^^^^^^^^^^^
  File "C:\ProgramData\anaconda3\envs\django\Lib\site-packages\django\template\response.py", line 90, in rendered_content
    template = self.resolve_template(self.template_name)
               ^^^^^^^^^^^^^^^^^^^^^^^^^^^^^^^^^^^^^^^^^
  File "C:\ProgramData\anaconda3\envs\django\Lib\site-packages\django\template\response.py", line 72, in resolve_template
    return select_template(template, using=self.using)
           ^^^^^^^^^^^^^^^^^^^^^^^^^^^^^^^^^^^^^^^^^^^
  File "C:\ProgramData\anaconda3\envs\django\Lib\site-packages\django\template\loader.py", line 42, in select_template
    return engine.get_template(template_name)
           ^^^^^^^^^^^^^^^^^^^^^^^^^^^^^^^^^^
  File "C:\ProgramData\anaconda3\envs\django\Lib\site-packages\django\template\backends\django.py", line 33, in get_template
    return Template(self.engine.get_template(template_name), self)
                    ^^^^^^^^^^^^^^^^^^^^^^^^^^^^^^^^^^^^^^^
  File "C:\ProgramData\anaconda3\envs\django\Lib\site-packages\django\template\engine.py", line 175, in get_template
    template, origin = self.find_template(template_name)
                       ^^^^^^^^^^^^^^^^^^^^^^^^^^^^^^^^^
  File "C:\ProgramData\anaconda3\envs\django\Lib\site-packages\django\template\engine.py", line 157, in find_template
    template = loader.get_template(name, skip=skip)
               ^^^^^^^^^^^^^^^^^^^^^^^^^^^^^^^^^^^^
  File "C:\ProgramData\anaconda3\envs\django\Lib\site-packages\django\template\loaders\cached.py", line 57, in get_template
    template = super().get_template(template_name, skip)
               ^^^^^^^^^^^^^^^^^^^^^^^^^^^^^^^^^^^^^^^^^
  File "C:\ProgramData\anaconda3\envs\django\Lib\site-packages\django\template\loaders\base.py", line 28, in get_template
    return Template(
           ^^^^^^^^^
  File "C:\ProgramData\anaconda3\envs\django\Lib\site-packages\django\template\base.py", line 154, in __init__
    self.nodelist = self.compile_nodelist()
                    ^^^^^^^^^^^^^^^^^^^^^^^
  File "C:\ProgramData\anaconda3\envs\django\Lib\site-packages\django\template\base.py", line 200, in compile_nodelist
    return parser.parse()
           ^^^^^^^^^^^^^^
  File "C:\ProgramData\anaconda3\envs\django\Lib\site-packages\django\template\base.py", line 513, in parse
    raise self.error(token, e)
  File "C:\ProgramData\anaconda3\envs\django\Lib\site-packages\django\template\base.py", line 511, in parse
    compiled_result = compile_func(self, token)
                      ^^^^^^^^^^^^^^^^^^^^^^^^^
  File "C:\ProgramData\anaconda3\envs\django\Lib\site-packages\django\template\loader_tags.py", line 293, in do_extends
    nodelist = parser.parse()
               ^^^^^^^^^^^^^^
  File "C:\ProgramData\anaconda3\envs\django\Lib\site-packages\django\template\base.py", line 513, in parse
    raise self.error(token, e)
  File "C:\ProgramData\anaconda3\envs\django\Lib\site-packages\django\template\base.py", line 511, in parse
    compiled_result = compile_func(self, token)
                      ^^^^^^^^^^^^^^^^^^^^^^^^^
  File "C:\ProgramData\anaconda3\envs\django\Lib\site-packages\django\template\loader_tags.py", line 232, in do_block
    nodelist = parser.parse(("endblock",))
               ^^^^^^^^^^^^^^^^^^^^^^^^^^^
  File "C:\ProgramData\anaconda3\envs\django\Lib\site-packages\django\template\base.py", line 507, in parse
    self.invalid_block_tag(token, command, parse_until)
  File "C:\ProgramData\anaconda3\envs\django\Lib\site-packages\django\template\base.py", line 558, in invalid_block_tag
    raise self.error(
django.template.exceptions.TemplateSyntaxError: Invalid block tag on line 15: 'buttons', expected 'endblock'. Did you forget to register or load this tag?
Internal Server Error: /minerva/import_tests/
Traceback (most recent call last):
  File "C:\ProgramData\anaconda3\envs\django\Lib\site-packages\django\template\base.py", line 505, in parse
    compile_func = self.tags[command]
                   ~~~~~~~~~^^^^^^^^^
KeyError: 'bootstrap_icon'

During handling of the above exception, another exception occurred:

Traceback (most recent call last):
  File "C:\ProgramData\anaconda3\envs\django\Lib\site-packages\django\core\handlers\exception.py", line 55, in inner
    response = get_response(request)
               ^^^^^^^^^^^^^^^^^^^^^
  File "C:\ProgramData\anaconda3\envs\django\Lib\site-packages\django\core\handlers\base.py", line 220, in _get_response
    response = response.render()
               ^^^^^^^^^^^^^^^^^
  File "C:\ProgramData\anaconda3\envs\django\Lib\site-packages\django\template\response.py", line 114, in render
    self.content = self.rendered_content
                   ^^^^^^^^^^^^^^^^^^^^^
  File "C:\ProgramData\anaconda3\envs\django\Lib\site-packages\django\template\response.py", line 90, in rendered_content
    template = self.resolve_template(self.template_name)
               ^^^^^^^^^^^^^^^^^^^^^^^^^^^^^^^^^^^^^^^^^
  File "C:\ProgramData\anaconda3\envs\django\Lib\site-packages\django\template\response.py", line 72, in resolve_template
    return select_template(template, using=self.using)
           ^^^^^^^^^^^^^^^^^^^^^^^^^^^^^^^^^^^^^^^^^^^
  File "C:\ProgramData\anaconda3\envs\django\Lib\site-packages\django\template\loader.py", line 42, in select_template
    return engine.get_template(template_name)
           ^^^^^^^^^^^^^^^^^^^^^^^^^^^^^^^^^^
  File "C:\ProgramData\anaconda3\envs\django\Lib\site-packages\django\template\backends\django.py", line 33, in get_template
    return Template(self.engine.get_template(template_name), self)
                    ^^^^^^^^^^^^^^^^^^^^^^^^^^^^^^^^^^^^^^^
  File "C:\ProgramData\anaconda3\envs\django\Lib\site-packages\django\template\engine.py", line 175, in get_template
    template, origin = self.find_template(template_name)
                       ^^^^^^^^^^^^^^^^^^^^^^^^^^^^^^^^^
  File "C:\ProgramData\anaconda3\envs\django\Lib\site-packages\django\template\engine.py", line 157, in find_template
    template = loader.get_template(name, skip=skip)
               ^^^^^^^^^^^^^^^^^^^^^^^^^^^^^^^^^^^^
  File "C:\ProgramData\anaconda3\envs\django\Lib\site-packages\django\template\loaders\cached.py", line 57, in get_template
    template = super().get_template(template_name, skip)
               ^^^^^^^^^^^^^^^^^^^^^^^^^^^^^^^^^^^^^^^^^
  File "C:\ProgramData\anaconda3\envs\django\Lib\site-packages\django\template\loaders\base.py", line 28, in get_template
    return Template(
           ^^^^^^^^^
  File "C:\ProgramData\anaconda3\envs\django\Lib\site-packages\django\template\base.py", line 154, in __init__
    self.nodelist = self.compile_nodelist()
                    ^^^^^^^^^^^^^^^^^^^^^^^
  File "C:\ProgramData\anaconda3\envs\django\Lib\site-packages\django\template\base.py", line 200, in compile_nodelist
    return parser.parse()
           ^^^^^^^^^^^^^^
  File "C:\ProgramData\anaconda3\envs\django\Lib\site-packages\django\template\base.py", line 513, in parse
    raise self.error(token, e)
  File "C:\ProgramData\anaconda3\envs\django\Lib\site-packages\django\template\base.py", line 511, in parse
    compiled_result = compile_func(self, token)
                      ^^^^^^^^^^^^^^^^^^^^^^^^^
  File "C:\ProgramData\anaconda3\envs\django\Lib\site-packages\django\template\loader_tags.py", line 293, in do_extends
    nodelist = parser.parse()
               ^^^^^^^^^^^^^^
  File "C:\ProgramData\anaconda3\envs\django\Lib\site-packages\django\template\base.py", line 513, in parse
    raise self.error(token, e)
  File "C:\ProgramData\anaconda3\envs\django\Lib\site-packages\django\template\base.py", line 511, in parse
    compiled_result = compile_func(self, token)
                      ^^^^^^^^^^^^^^^^^^^^^^^^^
  File "C:\ProgramData\anaconda3\envs\django\Lib\site-packages\django\template\loader_tags.py", line 232, in do_block
    nodelist = parser.parse(("endblock",))
               ^^^^^^^^^^^^^^^^^^^^^^^^^^^
  File "C:\ProgramData\anaconda3\envs\django\Lib\site-packages\django\template\base.py", line 507, in parse
    self.invalid_block_tag(token, command, parse_until)
  File "C:\ProgramData\anaconda3\envs\django\Lib\site-packages\django\template\base.py", line 558, in invalid_block_tag
    raise self.error(
django.template.exceptions.TemplateSyntaxError: Invalid block tag on line 16: 'bootstrap_icon', expected 'endblock'. Did you forget to register or load this tag?
Internal Server Error: /minerva/import_tests/
Traceback (most recent call last):
  File "C:\ProgramData\anaconda3\envs\django\Lib\site-packages\django\core\handlers\exception.py", line 55, in inner
    response = get_response(request)
               ^^^^^^^^^^^^^^^^^^^^^
  File "C:\ProgramData\anaconda3\envs\django\Lib\site-packages\django\core\handlers\base.py", line 197, in _get_response
    response = wrapped_callback(request, *callback_args, **callback_kwargs)
               ^^^^^^^^^^^^^^^^^^^^^^^^^^^^^^^^^^^^^^^^^^^^^^^^^^^^^^^^^^^^
  File "C:\ProgramData\anaconda3\envs\django\Lib\site-packages\django\views\generic\base.py", line 104, in view
    return self.dispatch(request, *args, **kwargs)
           ^^^^^^^^^^^^^^^^^^^^^^^^^^^^^^^^^^^^^^^
  File "C:\ProgramData\anaconda3\envs\django\Lib\site-packages\django\contrib\auth\mixins.py", line 135, in dispatch
    return super().dispatch(request, *args, **kwargs)
           ^^^^^^^^^^^^^^^^^^^^^^^^^^^^^^^^^^^^^^^^^^
  File "C:\ProgramData\anaconda3\envs\django\Lib\site-packages\django\views\generic\base.py", line 143, in dispatch
    return handler(request, *args, **kwargs)
           ^^^^^^^^^^^^^^^^^^^^^^^^^^^^^^^^^
  File "C:\Users\gavin\OneDrive - University of Leeds\Documents\Programming\phas_vitals\apps\minerva\views.py", line 32, in post
    if form.is_valid():
       ^^^^^^^^^^^^^^^
  File "C:\ProgramData\anaconda3\envs\django\Lib\site-packages\django\forms\forms.py", line 201, in is_valid
    return self.is_bound and not self.errors
                                 ^^^^^^^^^^^
  File "C:\ProgramData\anaconda3\envs\django\Lib\site-packages\django\forms\forms.py", line 196, in errors
    self.full_clean()
  File "C:\ProgramData\anaconda3\envs\django\Lib\site-packages\django\forms\forms.py", line 433, in full_clean
    self._clean_fields()
  File "C:\ProgramData\anaconda3\envs\django\Lib\site-packages\django\forms\forms.py", line 448, in _clean_fields
    value = getattr(self, "clean_%s" % name)()
            ^^^^^^^^^^^^^^^^^^^^^^^^^^^^^^^^^^
  File "C:\Users\gavin\OneDrive - University of Leeds\Documents\Programming\phas_vitals\apps\minerva\forms.py", line 33, in clean_spreadsheet
    assert False
AssertionError
Internal Server Error: /minerva/import_tests/
Traceback (most recent call last):
  File "C:\ProgramData\anaconda3\envs\django\Lib\site-packages\django\core\handlers\exception.py", line 55, in inner
    response = get_response(request)
               ^^^^^^^^^^^^^^^^^^^^^
  File "C:\ProgramData\anaconda3\envs\django\Lib\site-packages\django\core\handlers\base.py", line 197, in _get_response
    response = wrapped_callback(request, *callback_args, **callback_kwargs)
               ^^^^^^^^^^^^^^^^^^^^^^^^^^^^^^^^^^^^^^^^^^^^^^^^^^^^^^^^^^^^
  File "C:\ProgramData\anaconda3\envs\django\Lib\site-packages\django\views\generic\base.py", line 104, in view
    return self.dispatch(request, *args, **kwargs)
           ^^^^^^^^^^^^^^^^^^^^^^^^^^^^^^^^^^^^^^^
  File "C:\ProgramData\anaconda3\envs\django\Lib\site-packages\django\contrib\auth\mixins.py", line 135, in dispatch
    return super().dispatch(request, *args, **kwargs)
           ^^^^^^^^^^^^^^^^^^^^^^^^^^^^^^^^^^^^^^^^^^
  File "C:\ProgramData\anaconda3\envs\django\Lib\site-packages\django\views\generic\base.py", line 143, in dispatch
    return handler(request, *args, **kwargs)
           ^^^^^^^^^^^^^^^^^^^^^^^^^^^^^^^^^
  File "C:\Users\gavin\OneDrive - University of Leeds\Documents\Programming\phas_vitals\apps\minerva\views.py", line 34, in post
    raise ValidationError("Expecting one or more files.")
django.core.exceptions.ValidationError: ['Expecting one or more files.']
Internal Server Error: /minerva/import_tests/
Traceback (most recent call last):
  File "C:\Users\gavin\OneDrive - University of Leeds\Documents\Programming\phas_vitals\apps\minerva\views.py", line 38, in post
    df = pd.read_excel(f.temporary_file_path())
                       ^^^^^^^^^^^^^^^^^^^^^
AttributeError: 'InMemoryUploadedFile' object has no attribute 'temporary_file_path'

During handling of the above exception, another exception occurred:

Traceback (most recent call last):
  File "C:\ProgramData\anaconda3\envs\django\Lib\site-packages\django\core\handlers\exception.py", line 55, in inner
    response = get_response(request)
               ^^^^^^^^^^^^^^^^^^^^^
  File "C:\ProgramData\anaconda3\envs\django\Lib\site-packages\django\core\handlers\base.py", line 197, in _get_response
    response = wrapped_callback(request, *callback_args, **callback_kwargs)
               ^^^^^^^^^^^^^^^^^^^^^^^^^^^^^^^^^^^^^^^^^^^^^^^^^^^^^^^^^^^^
  File "C:\ProgramData\anaconda3\envs\django\Lib\site-packages\django\views\generic\base.py", line 104, in view
    return self.dispatch(request, *args, **kwargs)
           ^^^^^^^^^^^^^^^^^^^^^^^^^^^^^^^^^^^^^^^
  File "C:\ProgramData\anaconda3\envs\django\Lib\site-packages\django\contrib\auth\mixins.py", line 135, in dispatch
    return super().dispatch(request, *args, **kwargs)
           ^^^^^^^^^^^^^^^^^^^^^^^^^^^^^^^^^^^^^^^^^^
  File "C:\ProgramData\anaconda3\envs\django\Lib\site-packages\django\views\generic\base.py", line 143, in dispatch
    return handler(request, *args, **kwargs)
           ^^^^^^^^^^^^^^^^^^^^^^^^^^^^^^^^^
  File "C:\Users\gavin\OneDrive - University of Leeds\Documents\Programming\phas_vitals\apps\minerva\views.py", line 48, in post
    None, f"Could not read Progression file due to: {e} with {f.temporary_file_path()} {format_exc()}"
                                                              ^^^^^^^^^^^^^^^^^^^^^
AttributeError: 'InMemoryUploadedFile' object has no attribute 'temporary_file_path'
Internal Server Error: /minerva/import_tests/
Traceback (most recent call last):
  File "C:\ProgramData\anaconda3\envs\django\Lib\site-packages\django\core\handlers\exception.py", line 55, in inner
    response = get_response(request)
               ^^^^^^^^^^^^^^^^^^^^^
  File "C:\ProgramData\anaconda3\envs\django\Lib\site-packages\django\core\handlers\base.py", line 197, in _get_response
    response = wrapped_callback(request, *callback_args, **callback_kwargs)
               ^^^^^^^^^^^^^^^^^^^^^^^^^^^^^^^^^^^^^^^^^^^^^^^^^^^^^^^^^^^^
  File "C:\ProgramData\anaconda3\envs\django\Lib\site-packages\django\views\generic\base.py", line 104, in view
    return self.dispatch(request, *args, **kwargs)
           ^^^^^^^^^^^^^^^^^^^^^^^^^^^^^^^^^^^^^^^
  File "C:\ProgramData\anaconda3\envs\django\Lib\site-packages\django\contrib\auth\mixins.py", line 135, in dispatch
    return super().dispatch(request, *args, **kwargs)
           ^^^^^^^^^^^^^^^^^^^^^^^^^^^^^^^^^^^^^^^^^^
  File "C:\ProgramData\anaconda3\envs\django\Lib\site-packages\django\views\generic\base.py", line 143, in dispatch
    return handler(request, *args, **kwargs)
           ^^^^^^^^^^^^^^^^^^^^^^^^^^^^^^^^^
  File "C:\Users\gavin\OneDrive - University of Leeds\Documents\Programming\phas_vitals\apps\minerva\views.py", line 51, in post
    return self.form_valid(form)
           ^^^^^^^^^^^^^^^^^^^^^
  File "C:\Users\gavin\OneDrive - University of Leeds\Documents\Programming\phas_vitals\apps\minerva\views.py", line 63, in form_valid
    test_id = match.groupdict()["id"]
              ~~~~~~~~~~~~~~~~~^^^^^^
KeyError: 'id'
Internal Server Error: /minerva/import_tests/
Traceback (most recent call last):
  File "C:\ProgramData\anaconda3\envs\django\Lib\site-packages\django\db\models\query.py", line 916, in get_or_create
    return self.get(**kwargs), False
           ^^^^^^^^^^^^^^^^^^
  File "C:\ProgramData\anaconda3\envs\django\Lib\site-packages\django\db\models\query.py", line 637, in get
    raise self.model.DoesNotExist(
minerva.models.Test.DoesNotExist: Test matching query does not exist.

During handling of the above exception, another exception occurred:

Traceback (most recent call last):
  File "C:\ProgramData\anaconda3\envs\django\Lib\site-packages\django\db\backends\utils.py", line 89, in _execute
    return self.cursor.execute(sql, params)
           ^^^^^^^^^^^^^^^^^^^^^^^^^^^^^^^^
  File "C:\ProgramData\anaconda3\envs\django\Lib\site-packages\django\db\backends\sqlite3\base.py", line 328, in execute
    return super().execute(query, params)
           ^^^^^^^^^^^^^^^^^^^^^^^^^^^^^^
sqlite3.IntegrityError: NOT NULL constraint failed: minerva_test.module_id

The above exception was the direct cause of the following exception:

Traceback (most recent call last):
  File "C:\ProgramData\anaconda3\envs\django\Lib\site-packages\django\core\handlers\exception.py", line 55, in inner
    response = get_response(request)
               ^^^^^^^^^^^^^^^^^^^^^
  File "C:\ProgramData\anaconda3\envs\django\Lib\site-packages\django\core\handlers\base.py", line 197, in _get_response
    response = wrapped_callback(request, *callback_args, **callback_kwargs)
               ^^^^^^^^^^^^^^^^^^^^^^^^^^^^^^^^^^^^^^^^^^^^^^^^^^^^^^^^^^^^
  File "C:\ProgramData\anaconda3\envs\django\Lib\site-packages\django\views\generic\base.py", line 104, in view
    return self.dispatch(request, *args, **kwargs)
           ^^^^^^^^^^^^^^^^^^^^^^^^^^^^^^^^^^^^^^^
  File "C:\ProgramData\anaconda3\envs\django\Lib\site-packages\django\contrib\auth\mixins.py", line 135, in dispatch
    return super().dispatch(request, *args, **kwargs)
           ^^^^^^^^^^^^^^^^^^^^^^^^^^^^^^^^^^^^^^^^^^
  File "C:\ProgramData\anaconda3\envs\django\Lib\site-packages\django\views\generic\base.py", line 143, in dispatch
    return handler(request, *args, **kwargs)
           ^^^^^^^^^^^^^^^^^^^^^^^^^^^^^^^^^
  File "C:\Users\gavin\OneDrive - University of Leeds\Documents\Programming\phas_vitals\apps\minerva\views.py", line 51, in post
    return self.form_valid(form)
           ^^^^^^^^^^^^^^^^^^^^^
  File "C:\Users\gavin\OneDrive - University of Leeds\Documents\Programming\phas_vitals\apps\minerva\views.py", line 65, in form_valid
    test, new = Test.objects.get_or_create(test_id=test_id)
                ^^^^^^^^^^^^^^^^^^^^^^^^^^^^^^^^^^^^^^^^^^^
  File "C:\ProgramData\anaconda3\envs\django\Lib\site-packages\django\db\models\manager.py", line 87, in manager_method
    return getattr(self.get_queryset(), name)(*args, **kwargs)
           ^^^^^^^^^^^^^^^^^^^^^^^^^^^^^^^^^^^^^^^^^^^^^^^^^^^
  File "C:\ProgramData\anaconda3\envs\django\Lib\site-packages\django\db\models\query.py", line 923, in get_or_create
    return self.create(**params), True
           ^^^^^^^^^^^^^^^^^^^^^
  File "C:\ProgramData\anaconda3\envs\django\Lib\site-packages\django\db\models\query.py", line 658, in create
    obj.save(force_insert=True, using=self.db)
  File "C:\ProgramData\anaconda3\envs\django\Lib\site-packages\django\db\models\base.py", line 814, in save
    self.save_base(
  File "C:\ProgramData\anaconda3\envs\django\Lib\site-packages\django\db\models\base.py", line 877, in save_base
    updated = self._save_table(
              ^^^^^^^^^^^^^^^^^
  File "C:\ProgramData\anaconda3\envs\django\Lib\site-packages\django\db\models\base.py", line 1020, in _save_table
    results = self._do_insert(
              ^^^^^^^^^^^^^^^^
  File "C:\ProgramData\anaconda3\envs\django\Lib\site-packages\django\db\models\base.py", line 1061, in _do_insert
    return manager._insert(
           ^^^^^^^^^^^^^^^^
  File "C:\ProgramData\anaconda3\envs\django\Lib\site-packages\django\db\models\manager.py", line 87, in manager_method
    return getattr(self.get_queryset(), name)(*args, **kwargs)
           ^^^^^^^^^^^^^^^^^^^^^^^^^^^^^^^^^^^^^^^^^^^^^^^^^^^
  File "C:\ProgramData\anaconda3\envs\django\Lib\site-packages\django\db\models\query.py", line 1805, in _insert
    return query.get_compiler(using=using).execute_sql(returning_fields)
           ^^^^^^^^^^^^^^^^^^^^^^^^^^^^^^^^^^^^^^^^^^^^^^^^^^^^^^^^^^^^^
  File "C:\ProgramData\anaconda3\envs\django\Lib\site-packages\django\db\models\sql\compiler.py", line 1822, in execute_sql
    cursor.execute(sql, params)
  File "C:\ProgramData\anaconda3\envs\django\Lib\site-packages\django\db\backends\utils.py", line 102, in execute
    return super().execute(sql, params)
           ^^^^^^^^^^^^^^^^^^^^^^^^^^^^
  File "C:\ProgramData\anaconda3\envs\django\Lib\site-packages\django\db\backends\utils.py", line 67, in execute
    return self._execute_with_wrappers(
           ^^^^^^^^^^^^^^^^^^^^^^^^^^^^
  File "C:\ProgramData\anaconda3\envs\django\Lib\site-packages\django\db\backends\utils.py", line 80, in _execute_with_wrappers
    return executor(sql, params, many, context)
           ^^^^^^^^^^^^^^^^^^^^^^^^^^^^^^^^^^^^
  File "C:\ProgramData\anaconda3\envs\django\Lib\site-packages\django\db\backends\utils.py", line 84, in _execute
    with self.db.wrap_database_errors:
  File "C:\ProgramData\anaconda3\envs\django\Lib\site-packages\django\db\utils.py", line 91, in __exit__
    raise dj_exc_value.with_traceback(traceback) from exc_value
  File "C:\ProgramData\anaconda3\envs\django\Lib\site-packages\django\db\backends\utils.py", line 89, in _execute
    return self.cursor.execute(sql, params)
           ^^^^^^^^^^^^^^^^^^^^^^^^^^^^^^^^
  File "C:\ProgramData\anaconda3\envs\django\Lib\site-packages\django\db\backends\sqlite3\base.py", line 328, in execute
    return super().execute(query, params)
           ^^^^^^^^^^^^^^^^^^^^^^^^^^^^^^
django.db.utils.IntegrityError: NOT NULL constraint failed: minerva_test.module_id
Internal Server Error: /minerva/import_tests/
Traceback (most recent call last):
  File "C:\ProgramData\anaconda3\envs\django\Lib\site-packages\django\core\handlers\exception.py", line 55, in inner
    response = get_response(request)
               ^^^^^^^^^^^^^^^^^^^^^
  File "C:\ProgramData\anaconda3\envs\django\Lib\site-packages\django\core\handlers\base.py", line 197, in _get_response
    response = wrapped_callback(request, *callback_args, **callback_kwargs)
               ^^^^^^^^^^^^^^^^^^^^^^^^^^^^^^^^^^^^^^^^^^^^^^^^^^^^^^^^^^^^
  File "C:\ProgramData\anaconda3\envs\django\Lib\site-packages\django\views\generic\base.py", line 104, in view
    return self.dispatch(request, *args, **kwargs)
           ^^^^^^^^^^^^^^^^^^^^^^^^^^^^^^^^^^^^^^^
  File "C:\ProgramData\anaconda3\envs\django\Lib\site-packages\django\contrib\auth\mixins.py", line 135, in dispatch
    return super().dispatch(request, *args, **kwargs)
           ^^^^^^^^^^^^^^^^^^^^^^^^^^^^^^^^^^^^^^^^^^
  File "C:\ProgramData\anaconda3\envs\django\Lib\site-packages\django\views\generic\base.py", line 143, in dispatch
    return handler(request, *args, **kwargs)
           ^^^^^^^^^^^^^^^^^^^^^^^^^^^^^^^^^
  File "C:\Users\gavin\OneDrive - University of Leeds\Documents\Programming\phas_vitals\apps\minerva\views.py", line 51, in post
    return self.form_valid(form)
           ^^^^^^^^^^^^^^^^^^^^^
  File "C:\Users\gavin\OneDrive - University of Leeds\Documents\Programming\phas_vitals\apps\minerva\views.py", line 71, in form_valid
    test.passing_score = 0.8*possible
                         ~~~^~~~~~~~~
TypeError: can't multiply sequence by non-int of type 'float'
Internal Server Error: /minerva/import_history/
Traceback (most recent call last):
  File "C:\ProgramData\anaconda3\envs\django\Lib\site-packages\django\core\handlers\exception.py", line 55, in inner
    response = get_response(request)
               ^^^^^^^^^^^^^^^^^^^^^
  File "C:\ProgramData\anaconda3\envs\django\Lib\site-packages\django\core\handlers\base.py", line 197, in _get_response
    response = wrapped_callback(request, *callback_args, **callback_kwargs)
               ^^^^^^^^^^^^^^^^^^^^^^^^^^^^^^^^^^^^^^^^^^^^^^^^^^^^^^^^^^^^
  File "C:\ProgramData\anaconda3\envs\django\Lib\site-packages\django\views\generic\base.py", line 104, in view
    return self.dispatch(request, *args, **kwargs)
           ^^^^^^^^^^^^^^^^^^^^^^^^^^^^^^^^^^^^^^^
  File "C:\ProgramData\anaconda3\envs\django\Lib\site-packages\django\contrib\auth\mixins.py", line 135, in dispatch
    return super().dispatch(request, *args, **kwargs)
           ^^^^^^^^^^^^^^^^^^^^^^^^^^^^^^^^^^^^^^^^^^
  File "C:\ProgramData\anaconda3\envs\django\Lib\site-packages\django\views\generic\base.py", line 143, in dispatch
    return handler(request, *args, **kwargs)
           ^^^^^^^^^^^^^^^^^^^^^^^^^^^^^^^^^
  File "C:\Users\gavin\OneDrive - University of Leeds\Documents\Programming\phas_vitals\apps\minerva\views.py", line 123, in post
    return self.form_valid(form)
           ^^^^^^^^^^^^^^^^^^^^^
  File "C:\Users\gavin\OneDrive - University of Leeds\Documents\Programming\phas_vitals\apps\minerva\views.py", line 135, in form_valid
    for row in df.iterows():
               ^^^^^^^^^^
  File "C:\ProgramData\anaconda3\envs\django\Lib\site-packages\pandas\core\generic.py", line 6293, in __getattr__
    return object.__getattribute__(self, name)
           ^^^^^^^^^^^^^^^^^^^^^^^^^^^^^^^^^^^
AttributeError: 'DataFrame' object has no attribute 'iterows'
Internal Server Error: /minerva/import_history/
Traceback (most recent call last):
  File "C:\ProgramData\anaconda3\envs\django\Lib\site-packages\django\core\handlers\exception.py", line 55, in inner
    response = get_response(request)
               ^^^^^^^^^^^^^^^^^^^^^
  File "C:\ProgramData\anaconda3\envs\django\Lib\site-packages\django\core\handlers\base.py", line 197, in _get_response
    response = wrapped_callback(request, *callback_args, **callback_kwargs)
               ^^^^^^^^^^^^^^^^^^^^^^^^^^^^^^^^^^^^^^^^^^^^^^^^^^^^^^^^^^^^
  File "C:\ProgramData\anaconda3\envs\django\Lib\site-packages\django\views\generic\base.py", line 104, in view
    return self.dispatch(request, *args, **kwargs)
           ^^^^^^^^^^^^^^^^^^^^^^^^^^^^^^^^^^^^^^^
  File "C:\ProgramData\anaconda3\envs\django\Lib\site-packages\django\contrib\auth\mixins.py", line 135, in dispatch
    return super().dispatch(request, *args, **kwargs)
           ^^^^^^^^^^^^^^^^^^^^^^^^^^^^^^^^^^^^^^^^^^
  File "C:\ProgramData\anaconda3\envs\django\Lib\site-packages\django\views\generic\base.py", line 143, in dispatch
    return handler(request, *args, **kwargs)
           ^^^^^^^^^^^^^^^^^^^^^^^^^^^^^^^^^
  File "C:\Users\gavin\OneDrive - University of Leeds\Documents\Programming\phas_vitals\apps\minerva\views.py", line 123, in post
    return self.form_valid(form)
           ^^^^^^^^^^^^^^^^^^^^^
  File "C:\Users\gavin\OneDrive - University of Leeds\Documents\Programming\phas_vitals\apps\minerva\views.py", line 136, in form_valid
    row_report={}|row
               ~~^~~~
TypeError: unsupported operand type(s) for |: 'dict' and 'tuple'
Internal Server Error: /minerva/import_history/
Traceback (most recent call last):
  File "C:\ProgramData\anaconda3\envs\django\Lib\site-packages\django\core\handlers\exception.py", line 55, in inner
    response = get_response(request)
               ^^^^^^^^^^^^^^^^^^^^^
  File "C:\ProgramData\anaconda3\envs\django\Lib\site-packages\django\core\handlers\base.py", line 197, in _get_response
    response = wrapped_callback(request, *callback_args, **callback_kwargs)
               ^^^^^^^^^^^^^^^^^^^^^^^^^^^^^^^^^^^^^^^^^^^^^^^^^^^^^^^^^^^^
  File "C:\ProgramData\anaconda3\envs\django\Lib\site-packages\django\views\generic\base.py", line 104, in view
    return self.dispatch(request, *args, **kwargs)
           ^^^^^^^^^^^^^^^^^^^^^^^^^^^^^^^^^^^^^^^
  File "C:\ProgramData\anaconda3\envs\django\Lib\site-packages\django\contrib\auth\mixins.py", line 135, in dispatch
    return super().dispatch(request, *args, **kwargs)
           ^^^^^^^^^^^^^^^^^^^^^^^^^^^^^^^^^^^^^^^^^^
  File "C:\ProgramData\anaconda3\envs\django\Lib\site-packages\django\views\generic\base.py", line 143, in dispatch
    return handler(request, *args, **kwargs)
           ^^^^^^^^^^^^^^^^^^^^^^^^^^^^^^^^^
  File "C:\Users\gavin\OneDrive - University of Leeds\Documents\Programming\phas_vitals\apps\minerva\views.py", line 123, in post
    return self.form_valid(form)
           ^^^^^^^^^^^^^^^^^^^^^
  File "C:\Users\gavin\OneDrive - University of Leeds\Documents\Programming\phas_vitals\apps\minerva\views.py", line 136, in form_valid
    row_report={}|row
               ~~^~~~
  File "C:\ProgramData\anaconda3\envs\django\Lib\site-packages\pandas\core\ops\common.py", line 76, in new_method
    return method(self, other)
           ^^^^^^^^^^^^^^^^^^^
  File "C:\ProgramData\anaconda3\envs\django\Lib\site-packages\pandas\core\arraylike.py", line 82, in __ror__
    return self._logical_method(other, roperator.ror_)
           ^^^^^^^^^^^^^^^^^^^^^^^^^^^^^^^^^^^^^^^^^^^
  File "C:\ProgramData\anaconda3\envs\django\Lib\site-packages\pandas\core\series.py", line 6110, in _logical_method
    res_values = ops.logical_op(lvalues, rvalues, op)
                 ^^^^^^^^^^^^^^^^^^^^^^^^^^^^^^^^^^^^
  File "C:\ProgramData\anaconda3\envs\django\Lib\site-packages\pandas\core\ops\array_ops.py", line 454, in logical_op
    res_values = na_logical_op(lvalues, rvalues, op)
                 ^^^^^^^^^^^^^^^^^^^^^^^^^^^^^^^^^^^
  File "C:\ProgramData\anaconda3\envs\django\Lib\site-packages\pandas\core\ops\array_ops.py", line 362, in na_logical_op
    result = op(x, y)
             ^^^^^^^^
  File "C:\ProgramData\anaconda3\envs\django\Lib\site-packages\pandas\core\roperator.py", line 58, in ror_
    return operator.or_(right, left)
           ^^^^^^^^^^^^^^^^^^^^^^^^^
ValueError: operands could not be broadcast together with shapes (0,) (18,) 
Internal Server Error: /minerva/import_history/
Traceback (most recent call last):
  File "C:\ProgramData\anaconda3\envs\django\Lib\site-packages\django\core\handlers\exception.py", line 55, in inner
    response = get_response(request)
               ^^^^^^^^^^^^^^^^^^^^^
  File "C:\ProgramData\anaconda3\envs\django\Lib\site-packages\django\core\handlers\base.py", line 197, in _get_response
    response = wrapped_callback(request, *callback_args, **callback_kwargs)
               ^^^^^^^^^^^^^^^^^^^^^^^^^^^^^^^^^^^^^^^^^^^^^^^^^^^^^^^^^^^^
  File "C:\ProgramData\anaconda3\envs\django\Lib\site-packages\django\views\generic\base.py", line 104, in view
    return self.dispatch(request, *args, **kwargs)
           ^^^^^^^^^^^^^^^^^^^^^^^^^^^^^^^^^^^^^^^
  File "C:\ProgramData\anaconda3\envs\django\Lib\site-packages\django\contrib\auth\mixins.py", line 135, in dispatch
    return super().dispatch(request, *args, **kwargs)
           ^^^^^^^^^^^^^^^^^^^^^^^^^^^^^^^^^^^^^^^^^^
  File "C:\ProgramData\anaconda3\envs\django\Lib\site-packages\django\views\generic\base.py", line 143, in dispatch
    return handler(request, *args, **kwargs)
           ^^^^^^^^^^^^^^^^^^^^^^^^^^^^^^^^^
  File "C:\Users\gavin\OneDrive - University of Leeds\Documents\Programming\phas_vitals\apps\minerva\views.py", line 123, in post
    return self.form_valid(form)
           ^^^^^^^^^^^^^^^^^^^^^
  File "C:\Users\gavin\OneDrive - University of Leeds\Documents\Programming\phas_vitals\apps\minerva\views.py", line 138, in form_valid
    student=Account.objects.get(usernamne=row.Username)
            ^^^^^^^^^^^^^^^^^^^^^^^^^^^^^^^^^^^^^^^^^^^
  File "C:\ProgramData\anaconda3\envs\django\Lib\site-packages\django\db\models\manager.py", line 87, in manager_method
    return getattr(self.get_queryset(), name)(*args, **kwargs)
           ^^^^^^^^^^^^^^^^^^^^^^^^^^^^^^^^^^^^^^^^^^^^^^^^^^^
  File "C:\ProgramData\anaconda3\envs\django\Lib\site-packages\django\db\models\query.py", line 623, in get
    clone = self._chain() if self.query.combinator else self.filter(*args, **kwargs)
                                                        ^^^^^^^^^^^^^^^^^^^^^^^^^^^^
  File "C:\ProgramData\anaconda3\envs\django\Lib\site-packages\django\db\models\query.py", line 1436, in filter
    return self._filter_or_exclude(False, args, kwargs)
           ^^^^^^^^^^^^^^^^^^^^^^^^^^^^^^^^^^^^^^^^^^^^
  File "C:\ProgramData\anaconda3\envs\django\Lib\site-packages\django\db\models\query.py", line 1454, in _filter_or_exclude
    clone._filter_or_exclude_inplace(negate, args, kwargs)
  File "C:\ProgramData\anaconda3\envs\django\Lib\site-packages\django\db\models\query.py", line 1461, in _filter_or_exclude_inplace
    self._query.add_q(Q(*args, **kwargs))
  File "C:\ProgramData\anaconda3\envs\django\Lib\site-packages\django\db\models\sql\query.py", line 1534, in add_q
    clause, _ = self._add_q(q_object, self.used_aliases)
                ^^^^^^^^^^^^^^^^^^^^^^^^^^^^^^^^^^^^^^^^
  File "C:\ProgramData\anaconda3\envs\django\Lib\site-packages\django\db\models\sql\query.py", line 1565, in _add_q
    child_clause, needed_inner = self.build_filter(
                                 ^^^^^^^^^^^^^^^^^^
  File "C:\ProgramData\anaconda3\envs\django\Lib\site-packages\django\db\models\sql\query.py", line 1415, in build_filter
    lookups, parts, reffed_expression = self.solve_lookup_type(arg, summarize)
                                        ^^^^^^^^^^^^^^^^^^^^^^^^^^^^^^^^^^^^^^
  File "C:\ProgramData\anaconda3\envs\django\Lib\site-packages\django\db\models\sql\query.py", line 1225, in solve_lookup_type
    _, field, _, lookup_parts = self.names_to_path(lookup_splitted, self.get_meta())
                                ^^^^^^^^^^^^^^^^^^^^^^^^^^^^^^^^^^^^^^^^^^^^^^^^^^^^
  File "C:\ProgramData\anaconda3\envs\django\Lib\site-packages\django\db\models\sql\query.py", line 1713, in names_to_path
    raise FieldError(
django.core.exceptions.FieldError: Cannot resolve keyword 'usernamne' into field. Choices are: VITALS, apt, apt_id, cohort, cohort_id, date_joined, email, first_name, groups, id, is_active, is_staff, is_superuser, last_login, last_name, level, logentry, number, oauth2_provider_accesstoken, oauth2_provider_application, oauth2_provider_grant, oauth2_provider_idtoken, oauth2_provider_refreshtoken, password, programme, programme_id, registration_status, test_results, title, tutees, user_permissions, username, vital_results
Internal Server Error: /minerva/import_history/
Traceback (most recent call last):
  File "C:\ProgramData\anaconda3\envs\django\Lib\site-packages\django\db\models\query.py", line 916, in get_or_create
    return self.get(**kwargs), False
           ^^^^^^^^^^^^^^^^^^
  File "C:\ProgramData\anaconda3\envs\django\Lib\site-packages\django\db\models\query.py", line 637, in get
    raise self.model.DoesNotExist(
minerva.models.Test_Score.DoesNotExist: Test_Score matching query does not exist.

During handling of the above exception, another exception occurred:

Traceback (most recent call last):
  File "C:\ProgramData\anaconda3\envs\django\Lib\site-packages\django\core\handlers\exception.py", line 55, in inner
    response = get_response(request)
               ^^^^^^^^^^^^^^^^^^^^^
  File "C:\ProgramData\anaconda3\envs\django\Lib\site-packages\django\core\handlers\base.py", line 197, in _get_response
    response = wrapped_callback(request, *callback_args, **callback_kwargs)
               ^^^^^^^^^^^^^^^^^^^^^^^^^^^^^^^^^^^^^^^^^^^^^^^^^^^^^^^^^^^^
  File "C:\ProgramData\anaconda3\envs\django\Lib\site-packages\django\views\generic\base.py", line 104, in view
    return self.dispatch(request, *args, **kwargs)
           ^^^^^^^^^^^^^^^^^^^^^^^^^^^^^^^^^^^^^^^
  File "C:\ProgramData\anaconda3\envs\django\Lib\site-packages\django\contrib\auth\mixins.py", line 135, in dispatch
    return super().dispatch(request, *args, **kwargs)
           ^^^^^^^^^^^^^^^^^^^^^^^^^^^^^^^^^^^^^^^^^^
  File "C:\ProgramData\anaconda3\envs\django\Lib\site-packages\django\views\generic\base.py", line 143, in dispatch
    return handler(request, *args, **kwargs)
           ^^^^^^^^^^^^^^^^^^^^^^^^^^^^^^^^^
  File "C:\Users\gavin\OneDrive - University of Leeds\Documents\Programming\phas_vitals\apps\minerva\views.py", line 123, in post
    return self.form_valid(form)
           ^^^^^^^^^^^^^^^^^^^^^
  File "C:\Users\gavin\OneDrive - University of Leeds\Documents\Programming\phas_vitals\apps\minerva\views.py", line 145, in form_valid
    test_score,new = Test_Score.objects.get_or_create(user=student,test=test)
                     ^^^^^^^^^^^^^^^^^^^^^^^^^^^^^^^^^^^^^^^^^^^^^^^^^^^^^^^^
  File "C:\ProgramData\anaconda3\envs\django\Lib\site-packages\django\db\models\manager.py", line 87, in manager_method
    return getattr(self.get_queryset(), name)(*args, **kwargs)
           ^^^^^^^^^^^^^^^^^^^^^^^^^^^^^^^^^^^^^^^^^^^^^^^^^^^
  File "C:\ProgramData\anaconda3\envs\django\Lib\site-packages\django\db\models\query.py", line 923, in get_or_create
    return self.create(**params), True
           ^^^^^^^^^^^^^^^^^^^^^
  File "C:\ProgramData\anaconda3\envs\django\Lib\site-packages\django\db\models\query.py", line 658, in create
    obj.save(force_insert=True, using=self.db)
  File "C:\Users\gavin\OneDrive - University of Leeds\Documents\Programming\phas_vitals\apps\minerva\models.py", line 76, in save
    numerically_passed = self.score >= self.test.passing_score
                         ^^^^^^^^^^^^^^^^^^^^^^^^^^^^^^^^^^^^^
TypeError: '>=' not supported between instances of 'NoneType' and 'float'
Internal Server Error: /minerva/import_history/
Traceback (most recent call last):
  File "C:\ProgramData\anaconda3\envs\django\Lib\site-packages\django\core\handlers\exception.py", line 55, in inner
    response = get_response(request)
               ^^^^^^^^^^^^^^^^^^^^^
  File "C:\ProgramData\anaconda3\envs\django\Lib\site-packages\django\core\handlers\base.py", line 197, in _get_response
    response = wrapped_callback(request, *callback_args, **callback_kwargs)
               ^^^^^^^^^^^^^^^^^^^^^^^^^^^^^^^^^^^^^^^^^^^^^^^^^^^^^^^^^^^^
  File "C:\ProgramData\anaconda3\envs\django\Lib\site-packages\django\views\generic\base.py", line 104, in view
    return self.dispatch(request, *args, **kwargs)
           ^^^^^^^^^^^^^^^^^^^^^^^^^^^^^^^^^^^^^^^
  File "C:\ProgramData\anaconda3\envs\django\Lib\site-packages\django\contrib\auth\mixins.py", line 135, in dispatch
    return super().dispatch(request, *args, **kwargs)
           ^^^^^^^^^^^^^^^^^^^^^^^^^^^^^^^^^^^^^^^^^^
  File "C:\ProgramData\anaconda3\envs\django\Lib\site-packages\django\views\generic\base.py", line 143, in dispatch
    return handler(request, *args, **kwargs)
           ^^^^^^^^^^^^^^^^^^^^^^^^^^^^^^^^^
  File "C:\Users\gavin\OneDrive - University of Leeds\Documents\Programming\phas_vitals\apps\minerva\views.py", line 123, in post
    return self.form_valid(form)
           ^^^^^^^^^^^^^^^^^^^^^
  File "C:\Users\gavin\OneDrive - University of Leeds\Documents\Programming\phas_vitals\apps\minerva\views.py", line 150, in form_valid
    test_attempt.modified=-row.Data
                           ^^^^^^^^
  File "C:\ProgramData\anaconda3\envs\django\Lib\site-packages\pandas\core\generic.py", line 6293, in __getattr__
    return object.__getattribute__(self, name)
           ^^^^^^^^^^^^^^^^^^^^^^^^^^^^^^^^^^^
AttributeError: 'Series' object has no attribute 'Data'
Internal Server Error: /minerva/import_history/
Traceback (most recent call last):
  File "C:\ProgramData\anaconda3\envs\django\Lib\site-packages\django\core\handlers\exception.py", line 55, in inner
    response = get_response(request)
               ^^^^^^^^^^^^^^^^^^^^^
  File "C:\ProgramData\anaconda3\envs\django\Lib\site-packages\django\core\handlers\base.py", line 197, in _get_response
    response = wrapped_callback(request, *callback_args, **callback_kwargs)
               ^^^^^^^^^^^^^^^^^^^^^^^^^^^^^^^^^^^^^^^^^^^^^^^^^^^^^^^^^^^^
  File "C:\ProgramData\anaconda3\envs\django\Lib\site-packages\django\views\generic\base.py", line 104, in view
    return self.dispatch(request, *args, **kwargs)
           ^^^^^^^^^^^^^^^^^^^^^^^^^^^^^^^^^^^^^^^
  File "C:\ProgramData\anaconda3\envs\django\Lib\site-packages\django\contrib\auth\mixins.py", line 135, in dispatch
    return super().dispatch(request, *args, **kwargs)
           ^^^^^^^^^^^^^^^^^^^^^^^^^^^^^^^^^^^^^^^^^^
  File "C:\ProgramData\anaconda3\envs\django\Lib\site-packages\django\views\generic\base.py", line 143, in dispatch
    return handler(request, *args, **kwargs)
           ^^^^^^^^^^^^^^^^^^^^^^^^^^^^^^^^^
  File "C:\Users\gavin\OneDrive - University of Leeds\Documents\Programming\phas_vitals\apps\minerva\views.py", line 123, in post
    return self.form_valid(form)
           ^^^^^^^^^^^^^^^^^^^^^
  File "C:\Users\gavin\OneDrive - University of Leeds\Documents\Programming\phas_vitals\apps\minerva\views.py", line 150, in form_valid
    test_attempt.modified=-row.Date
                          ^^^^^^^^^
TypeError: bad operand type for unary -: 'Timestamp'
Internal Server Error: /minerva/import_history/
Traceback (most recent call last):
  File "C:\ProgramData\anaconda3\envs\django\Lib\site-packages\django\core\handlers\exception.py", line 55, in inner
    response = get_response(request)
               ^^^^^^^^^^^^^^^^^^^^^
  File "C:\ProgramData\anaconda3\envs\django\Lib\site-packages\django\core\handlers\base.py", line 197, in _get_response
    response = wrapped_callback(request, *callback_args, **callback_kwargs)
               ^^^^^^^^^^^^^^^^^^^^^^^^^^^^^^^^^^^^^^^^^^^^^^^^^^^^^^^^^^^^
  File "C:\ProgramData\anaconda3\envs\django\Lib\site-packages\django\views\generic\base.py", line 104, in view
    return self.dispatch(request, *args, **kwargs)
           ^^^^^^^^^^^^^^^^^^^^^^^^^^^^^^^^^^^^^^^
  File "C:\ProgramData\anaconda3\envs\django\Lib\site-packages\django\contrib\auth\mixins.py", line 135, in dispatch
    return super().dispatch(request, *args, **kwargs)
           ^^^^^^^^^^^^^^^^^^^^^^^^^^^^^^^^^^^^^^^^^^
  File "C:\ProgramData\anaconda3\envs\django\Lib\site-packages\django\views\generic\base.py", line 143, in dispatch
    return handler(request, *args, **kwargs)
           ^^^^^^^^^^^^^^^^^^^^^^^^^^^^^^^^^
  File "C:\Users\gavin\OneDrive - University of Leeds\Documents\Programming\phas_vitals\apps\minerva\views.py", line 123, in post
    return self.form_valid(form)
           ^^^^^^^^^^^^^^^^^^^^^
  File "C:\Users\gavin\OneDrive - University of Leeds\Documents\Programming\phas_vitals\apps\minerva\views.py", line 150, in form_valid
    test_attempt.modified=-row.Date
                          ^^^^^^^^^
TypeError: bad operand type for unary -: 'Timestamp'
Internal Server Error: /minerva/import_history/
Traceback (most recent call last):
  File "C:\ProgramData\anaconda3\envs\django\Lib\site-packages\django\db\models\query.py", line 916, in get_or_create
    return self.get(**kwargs), False
           ^^^^^^^^^^^^^^^^^^
  File "C:\ProgramData\anaconda3\envs\django\Lib\site-packages\django\db\models\query.py", line 637, in get
    raise self.model.DoesNotExist(
minerva.models.Test_Attempt.DoesNotExist: Test_Attempt matching query does not exist.

During handling of the above exception, another exception occurred:

Traceback (most recent call last):
  File "C:\ProgramData\anaconda3\envs\django\Lib\site-packages\django\db\backends\utils.py", line 89, in _execute
    return self.cursor.execute(sql, params)
           ^^^^^^^^^^^^^^^^^^^^^^^^^^^^^^^^
  File "C:\ProgramData\anaconda3\envs\django\Lib\site-packages\django\db\backends\sqlite3\base.py", line 328, in execute
    return super().execute(query, params)
           ^^^^^^^^^^^^^^^^^^^^^^^^^^^^^^
sqlite3.IntegrityError: UNIQUE constraint failed: minerva_test_attempt.attempt_id

The above exception was the direct cause of the following exception:

Traceback (most recent call last):
  File "C:\ProgramData\anaconda3\envs\django\Lib\site-packages\django\core\handlers\exception.py", line 55, in inner
    response = get_response(request)
               ^^^^^^^^^^^^^^^^^^^^^
  File "C:\ProgramData\anaconda3\envs\django\Lib\site-packages\django\core\handlers\base.py", line 197, in _get_response
    response = wrapped_callback(request, *callback_args, **callback_kwargs)
               ^^^^^^^^^^^^^^^^^^^^^^^^^^^^^^^^^^^^^^^^^^^^^^^^^^^^^^^^^^^^
  File "C:\ProgramData\anaconda3\envs\django\Lib\site-packages\django\views\generic\base.py", line 104, in view
    return self.dispatch(request, *args, **kwargs)
           ^^^^^^^^^^^^^^^^^^^^^^^^^^^^^^^^^^^^^^^
  File "C:\ProgramData\anaconda3\envs\django\Lib\site-packages\django\contrib\auth\mixins.py", line 135, in dispatch
    return super().dispatch(request, *args, **kwargs)
           ^^^^^^^^^^^^^^^^^^^^^^^^^^^^^^^^^^^^^^^^^^
  File "C:\ProgramData\anaconda3\envs\django\Lib\site-packages\django\views\generic\base.py", line 143, in dispatch
    return handler(request, *args, **kwargs)
           ^^^^^^^^^^^^^^^^^^^^^^^^^^^^^^^^^
  File "C:\Users\gavin\OneDrive - University of Leeds\Documents\Programming\phas_vitals\apps\minerva\views.py", line 123, in post
    return self.form_valid(form)
           ^^^^^^^^^^^^^^^^^^^^^
  File "C:\Users\gavin\OneDrive - University of Leeds\Documents\Programming\phas_vitals\apps\minerva\views.py", line 148, in form_valid
    test_attempt, new=Test_Attempt.objects.get_or_create(test_entry=test_score, attempted=row["Attempt Activity"])
                      ^^^^^^^^^^^^^^^^^^^^^^^^^^^^^^^^^^^^^^^^^^^^^^^^^^^^^^^^^^^^^^^^^^^^^^^^^^^^^^^^^^^^^^^^^^^^
  File "C:\ProgramData\anaconda3\envs\django\Lib\site-packages\django\db\models\manager.py", line 87, in manager_method
    return getattr(self.get_queryset(), name)(*args, **kwargs)
           ^^^^^^^^^^^^^^^^^^^^^^^^^^^^^^^^^^^^^^^^^^^^^^^^^^^
  File "C:\ProgramData\anaconda3\envs\django\Lib\site-packages\django\db\models\query.py", line 923, in get_or_create
    return self.create(**params), True
           ^^^^^^^^^^^^^^^^^^^^^
  File "C:\ProgramData\anaconda3\envs\django\Lib\site-packages\django\db\models\query.py", line 658, in create
    obj.save(force_insert=True, using=self.db)
  File "C:\Users\gavin\OneDrive - University of Leeds\Documents\Programming\phas_vitals\apps\minerva\models.py", line 107, in save
    super().save(**kargs)
  File "C:\ProgramData\anaconda3\envs\django\Lib\site-packages\django\db\models\base.py", line 814, in save
    self.save_base(
  File "C:\ProgramData\anaconda3\envs\django\Lib\site-packages\django\db\models\base.py", line 877, in save_base
    updated = self._save_table(
              ^^^^^^^^^^^^^^^^^
  File "C:\ProgramData\anaconda3\envs\django\Lib\site-packages\django\db\models\base.py", line 1020, in _save_table
    results = self._do_insert(
              ^^^^^^^^^^^^^^^^
  File "C:\ProgramData\anaconda3\envs\django\Lib\site-packages\django\db\models\base.py", line 1061, in _do_insert
    return manager._insert(
           ^^^^^^^^^^^^^^^^
  File "C:\ProgramData\anaconda3\envs\django\Lib\site-packages\django\db\models\manager.py", line 87, in manager_method
    return getattr(self.get_queryset(), name)(*args, **kwargs)
           ^^^^^^^^^^^^^^^^^^^^^^^^^^^^^^^^^^^^^^^^^^^^^^^^^^^
  File "C:\ProgramData\anaconda3\envs\django\Lib\site-packages\django\db\models\query.py", line 1805, in _insert
    return query.get_compiler(using=using).execute_sql(returning_fields)
           ^^^^^^^^^^^^^^^^^^^^^^^^^^^^^^^^^^^^^^^^^^^^^^^^^^^^^^^^^^^^^
  File "C:\ProgramData\anaconda3\envs\django\Lib\site-packages\django\db\models\sql\compiler.py", line 1822, in execute_sql
    cursor.execute(sql, params)
  File "C:\ProgramData\anaconda3\envs\django\Lib\site-packages\django\db\backends\utils.py", line 102, in execute
    return super().execute(sql, params)
           ^^^^^^^^^^^^^^^^^^^^^^^^^^^^
  File "C:\ProgramData\anaconda3\envs\django\Lib\site-packages\django\db\backends\utils.py", line 67, in execute
    return self._execute_with_wrappers(
           ^^^^^^^^^^^^^^^^^^^^^^^^^^^^
  File "C:\ProgramData\anaconda3\envs\django\Lib\site-packages\django\db\backends\utils.py", line 80, in _execute_with_wrappers
    return executor(sql, params, many, context)
           ^^^^^^^^^^^^^^^^^^^^^^^^^^^^^^^^^^^^
  File "C:\ProgramData\anaconda3\envs\django\Lib\site-packages\django\db\backends\utils.py", line 84, in _execute
    with self.db.wrap_database_errors:
  File "C:\ProgramData\anaconda3\envs\django\Lib\site-packages\django\db\utils.py", line 91, in __exit__
    raise dj_exc_value.with_traceback(traceback) from exc_value
  File "C:\ProgramData\anaconda3\envs\django\Lib\site-packages\django\db\backends\utils.py", line 89, in _execute
    return self.cursor.execute(sql, params)
           ^^^^^^^^^^^^^^^^^^^^^^^^^^^^^^^^
  File "C:\ProgramData\anaconda3\envs\django\Lib\site-packages\django\db\backends\sqlite3\base.py", line 328, in execute
    return super().execute(query, params)
           ^^^^^^^^^^^^^^^^^^^^^^^^^^^^^^
django.db.utils.IntegrityError: UNIQUE constraint failed: minerva_test_attempt.attempt_id
Internal Server Error: /minerva/import_history/
Traceback (most recent call last):
  File "C:\ProgramData\anaconda3\envs\django\Lib\site-packages\django\core\handlers\exception.py", line 55, in inner
    response = get_response(request)
               ^^^^^^^^^^^^^^^^^^^^^
  File "C:\ProgramData\anaconda3\envs\django\Lib\site-packages\django\core\handlers\base.py", line 197, in _get_response
    response = wrapped_callback(request, *callback_args, **callback_kwargs)
               ^^^^^^^^^^^^^^^^^^^^^^^^^^^^^^^^^^^^^^^^^^^^^^^^^^^^^^^^^^^^
  File "C:\ProgramData\anaconda3\envs\django\Lib\site-packages\django\views\generic\base.py", line 104, in view
    return self.dispatch(request, *args, **kwargs)
           ^^^^^^^^^^^^^^^^^^^^^^^^^^^^^^^^^^^^^^^
  File "C:\ProgramData\anaconda3\envs\django\Lib\site-packages\django\contrib\auth\mixins.py", line 135, in dispatch
    return super().dispatch(request, *args, **kwargs)
           ^^^^^^^^^^^^^^^^^^^^^^^^^^^^^^^^^^^^^^^^^^
  File "C:\ProgramData\anaconda3\envs\django\Lib\site-packages\django\views\generic\base.py", line 143, in dispatch
    return handler(request, *args, **kwargs)
           ^^^^^^^^^^^^^^^^^^^^^^^^^^^^^^^^^
  File "C:\Users\gavin\OneDrive - University of Leeds\Documents\Programming\phas_vitals\apps\minerva\views.py", line 127, in post
    return self.form_valid(form)
           ^^^^^^^^^^^^^^^^^^^^^
  File "C:\Users\gavin\OneDrive - University of Leeds\Documents\Programming\phas_vitals\apps\minerva\views.py", line 153, in form_valid
    test_attempt, new = Test_Attempt.objects.get_or_create(
                        ^^^^^^^^^^^^^^^^^^^^^^^^^^^^^^^^^^^
  File "C:\ProgramData\anaconda3\envs\django\Lib\site-packages\django\db\models\manager.py", line 87, in manager_method
    return getattr(self.get_queryset(), name)(*args, **kwargs)
           ^^^^^^^^^^^^^^^^^^^^^^^^^^^^^^^^^^^^^^^^^^^^^^^^^^^
  File "C:\ProgramData\anaconda3\envs\django\Lib\site-packages\django\db\models\query.py", line 916, in get_or_create
    return self.get(**kwargs), False
           ^^^^^^^^^^^^^^^^^^
  File "C:\ProgramData\anaconda3\envs\django\Lib\site-packages\django\db\models\query.py", line 623, in get
    clone = self._chain() if self.query.combinator else self.filter(*args, **kwargs)
                                                        ^^^^^^^^^^^^^^^^^^^^^^^^^^^^
  File "C:\ProgramData\anaconda3\envs\django\Lib\site-packages\django\db\models\query.py", line 1436, in filter
    return self._filter_or_exclude(False, args, kwargs)
           ^^^^^^^^^^^^^^^^^^^^^^^^^^^^^^^^^^^^^^^^^^^^
  File "C:\ProgramData\anaconda3\envs\django\Lib\site-packages\django\db\models\query.py", line 1454, in _filter_or_exclude
    clone._filter_or_exclude_inplace(negate, args, kwargs)
  File "C:\ProgramData\anaconda3\envs\django\Lib\site-packages\django\db\models\query.py", line 1461, in _filter_or_exclude_inplace
    self._query.add_q(Q(*args, **kwargs))
  File "C:\ProgramData\anaconda3\envs\django\Lib\site-packages\django\db\models\sql\query.py", line 1534, in add_q
    clause, _ = self._add_q(q_object, self.used_aliases)
                ^^^^^^^^^^^^^^^^^^^^^^^^^^^^^^^^^^^^^^^^
  File "C:\ProgramData\anaconda3\envs\django\Lib\site-packages\django\db\models\sql\query.py", line 1565, in _add_q
    child_clause, needed_inner = self.build_filter(
                                 ^^^^^^^^^^^^^^^^^^
  File "C:\ProgramData\anaconda3\envs\django\Lib\site-packages\django\db\models\sql\query.py", line 1415, in build_filter
    lookups, parts, reffed_expression = self.solve_lookup_type(arg, summarize)
                                        ^^^^^^^^^^^^^^^^^^^^^^^^^^^^^^^^^^^^^^
  File "C:\ProgramData\anaconda3\envs\django\Lib\site-packages\django\db\models\sql\query.py", line 1225, in solve_lookup_type
    _, field, _, lookup_parts = self.names_to_path(lookup_splitted, self.get_meta())
                                ^^^^^^^^^^^^^^^^^^^^^^^^^^^^^^^^^^^^^^^^^^^^^^^^^^^^
  File "C:\ProgramData\anaconda3\envs\django\Lib\site-packages\django\db\models\sql\query.py", line 1713, in names_to_path
    raise FieldError(
django.core.exceptions.FieldError: Cannot resolve keyword 'test_id' into field. Choices are: attempt_id, attempted, created, modified, score, status, test_entry, test_entry_id, text
Internal Server Error: /minerva/import_history/
Traceback (most recent call last):
  File "C:\Users\gavin\OneDrive - University of Leeds\Documents\Programming\phas_vitals\apps\minerva\views.py", line 142, in form_valid
    student = Account.objects.get(username=row.Username)
              ^^^^^^^^^^^^^^^^^^^^^^^^^^^^^^^^^^^^^^^^^^
  File "C:\ProgramData\anaconda3\envs\django\Lib\site-packages\django\db\models\manager.py", line 87, in manager_method
    return getattr(self.get_queryset(), name)(*args, **kwargs)
           ^^^^^^^^^^^^^^^^^^^^^^^^^^^^^^^^^^^^^^^^^^^^^^^^^^^
  File "C:\ProgramData\anaconda3\envs\django\Lib\site-packages\django\db\models\query.py", line 637, in get
    raise self.model.DoesNotExist(
accounts.models.Account.DoesNotExist: Account matching query does not exist.

During handling of the above exception, another exception occurred:

Traceback (most recent call last):
  File "C:\ProgramData\anaconda3\envs\django\Lib\site-packages\django\core\handlers\exception.py", line 55, in inner
    response = get_response(request)
               ^^^^^^^^^^^^^^^^^^^^^
  File "C:\ProgramData\anaconda3\envs\django\Lib\site-packages\django\core\handlers\base.py", line 197, in _get_response
    response = wrapped_callback(request, *callback_args, **callback_kwargs)
               ^^^^^^^^^^^^^^^^^^^^^^^^^^^^^^^^^^^^^^^^^^^^^^^^^^^^^^^^^^^^
  File "C:\ProgramData\anaconda3\envs\django\Lib\site-packages\django\views\generic\base.py", line 104, in view
    return self.dispatch(request, *args, **kwargs)
           ^^^^^^^^^^^^^^^^^^^^^^^^^^^^^^^^^^^^^^^
  File "C:\ProgramData\anaconda3\envs\django\Lib\site-packages\django\contrib\auth\mixins.py", line 135, in dispatch
    return super().dispatch(request, *args, **kwargs)
           ^^^^^^^^^^^^^^^^^^^^^^^^^^^^^^^^^^^^^^^^^^
  File "C:\ProgramData\anaconda3\envs\django\Lib\site-packages\django\views\generic\base.py", line 143, in dispatch
    return handler(request, *args, **kwargs)
           ^^^^^^^^^^^^^^^^^^^^^^^^^^^^^^^^^
  File "C:\Users\gavin\OneDrive - University of Leeds\Documents\Programming\phas_vitals\apps\minerva\views.py", line 127, in post
    return self.form_valid(form)
           ^^^^^^^^^^^^^^^^^^^^^
  File "C:\Users\gavin\OneDrive - University of Leeds\Documents\Programming\phas_vitals\apps\minerva\views.py", line 144, in form_valid
    row_report["message"] = f"Unknown User {row.Usernbame}"
                                            ^^^^^^^^^^^^^
  File "C:\ProgramData\anaconda3\envs\django\Lib\site-packages\pandas\core\generic.py", line 6293, in __getattr__
    return object.__getattribute__(self, name)
           ^^^^^^^^^^^^^^^^^^^^^^^^^^^^^^^^^^^
AttributeError: 'Series' object has no attribute 'Usernbame'
Internal Server Error: /admin/minerva/test_score/1140/change/
Traceback (most recent call last):
  File "C:\ProgramData\anaconda3\envs\django\Lib\site-packages\django\core\handlers\exception.py", line 55, in inner
    response = get_response(request)
               ^^^^^^^^^^^^^^^^^^^^^
  File "C:\ProgramData\anaconda3\envs\django\Lib\site-packages\django\core\handlers\base.py", line 197, in _get_response
    response = wrapped_callback(request, *callback_args, **callback_kwargs)
               ^^^^^^^^^^^^^^^^^^^^^^^^^^^^^^^^^^^^^^^^^^^^^^^^^^^^^^^^^^^^
  File "C:\ProgramData\anaconda3\envs\django\Lib\site-packages\django\contrib\admin\options.py", line 688, in wrapper
    return self.admin_site.admin_view(view)(*args, **kwargs)
           ^^^^^^^^^^^^^^^^^^^^^^^^^^^^^^^^^^^^^^^^^^^^^^^^^
  File "C:\ProgramData\anaconda3\envs\django\Lib\site-packages\django\utils\decorators.py", line 134, in _wrapper_view
    response = view_func(request, *args, **kwargs)
               ^^^^^^^^^^^^^^^^^^^^^^^^^^^^^^^^^^^
  File "C:\ProgramData\anaconda3\envs\django\Lib\site-packages\django\views\decorators\cache.py", line 62, in _wrapper_view_func
    response = view_func(request, *args, **kwargs)
               ^^^^^^^^^^^^^^^^^^^^^^^^^^^^^^^^^^^
  File "C:\ProgramData\anaconda3\envs\django\Lib\site-packages\django\contrib\admin\sites.py", line 242, in inner
    return view(request, *args, **kwargs)
           ^^^^^^^^^^^^^^^^^^^^^^^^^^^^^^
  File "C:\ProgramData\anaconda3\envs\django\Lib\site-packages\django\contrib\admin\options.py", line 1889, in change_view
    return self.changeform_view(request, object_id, form_url, extra_context)
           ^^^^^^^^^^^^^^^^^^^^^^^^^^^^^^^^^^^^^^^^^^^^^^^^^^^^^^^^^^^^^^^^^
  File "C:\ProgramData\anaconda3\envs\django\Lib\site-packages\django\utils\decorators.py", line 46, in _wrapper
    return bound_method(*args, **kwargs)
           ^^^^^^^^^^^^^^^^^^^^^^^^^^^^^
  File "C:\ProgramData\anaconda3\envs\django\Lib\site-packages\django\utils\decorators.py", line 134, in _wrapper_view
    response = view_func(request, *args, **kwargs)
               ^^^^^^^^^^^^^^^^^^^^^^^^^^^^^^^^^^^
  File "C:\ProgramData\anaconda3\envs\django\Lib\site-packages\django\contrib\admin\options.py", line 1747, in changeform_view
    return self._changeform_view(request, object_id, form_url, extra_context)
           ^^^^^^^^^^^^^^^^^^^^^^^^^^^^^^^^^^^^^^^^^^^^^^^^^^^^^^^^^^^^^^^^^^
  File "C:\ProgramData\anaconda3\envs\django\Lib\site-packages\django\contrib\admin\options.py", line 1855, in _changeform_view
    "subtitle": str(obj) if obj else None,
                ^^^^^^^^
  File "C:\Users\gavin\OneDrive - University of Leeds\Documents\Programming\phas_vitals\apps\minerva\models.py", line 88, in __str__
    return f"{self.test.name} : {self.user.displayname} {'passed' if self.passed else 'not passed'}"
                                 ^^^^^^^^^^^^^^^^^^^^^
AttributeError: 'Account' object has no attribute 'displayname'
Internal Server Error: /admin/minerva/test_score/1140/change/
Traceback (most recent call last):
  File "C:\ProgramData\anaconda3\envs\django\Lib\site-packages\django\core\handlers\exception.py", line 55, in inner
    response = get_response(request)
               ^^^^^^^^^^^^^^^^^^^^^
  File "C:\ProgramData\anaconda3\envs\django\Lib\site-packages\django\core\handlers\base.py", line 197, in _get_response
    response = wrapped_callback(request, *callback_args, **callback_kwargs)
               ^^^^^^^^^^^^^^^^^^^^^^^^^^^^^^^^^^^^^^^^^^^^^^^^^^^^^^^^^^^^
  File "C:\ProgramData\anaconda3\envs\django\Lib\site-packages\django\contrib\admin\options.py", line 688, in wrapper
    return self.admin_site.admin_view(view)(*args, **kwargs)
           ^^^^^^^^^^^^^^^^^^^^^^^^^^^^^^^^^^^^^^^^^^^^^^^^^
  File "C:\ProgramData\anaconda3\envs\django\Lib\site-packages\django\utils\decorators.py", line 134, in _wrapper_view
    response = view_func(request, *args, **kwargs)
               ^^^^^^^^^^^^^^^^^^^^^^^^^^^^^^^^^^^
  File "C:\ProgramData\anaconda3\envs\django\Lib\site-packages\django\views\decorators\cache.py", line 62, in _wrapper_view_func
    response = view_func(request, *args, **kwargs)
               ^^^^^^^^^^^^^^^^^^^^^^^^^^^^^^^^^^^
  File "C:\ProgramData\anaconda3\envs\django\Lib\site-packages\django\contrib\admin\sites.py", line 242, in inner
    return view(request, *args, **kwargs)
           ^^^^^^^^^^^^^^^^^^^^^^^^^^^^^^
  File "C:\ProgramData\anaconda3\envs\django\Lib\site-packages\django\contrib\admin\options.py", line 1889, in change_view
    return self.changeform_view(request, object_id, form_url, extra_context)
           ^^^^^^^^^^^^^^^^^^^^^^^^^^^^^^^^^^^^^^^^^^^^^^^^^^^^^^^^^^^^^^^^^
  File "C:\ProgramData\anaconda3\envs\django\Lib\site-packages\django\utils\decorators.py", line 46, in _wrapper
    return bound_method(*args, **kwargs)
           ^^^^^^^^^^^^^^^^^^^^^^^^^^^^^
  File "C:\ProgramData\anaconda3\envs\django\Lib\site-packages\django\utils\decorators.py", line 134, in _wrapper_view
    response = view_func(request, *args, **kwargs)
               ^^^^^^^^^^^^^^^^^^^^^^^^^^^^^^^^^^^
  File "C:\ProgramData\anaconda3\envs\django\Lib\site-packages\django\contrib\admin\options.py", line 1747, in changeform_view
    return self._changeform_view(request, object_id, form_url, extra_context)
           ^^^^^^^^^^^^^^^^^^^^^^^^^^^^^^^^^^^^^^^^^^^^^^^^^^^^^^^^^^^^^^^^^^
  File "C:\ProgramData\anaconda3\envs\django\Lib\site-packages\django\contrib\admin\options.py", line 1855, in _changeform_view
    "subtitle": str(obj) if obj else None,
                ^^^^^^^^
  File "C:\Users\gavin\OneDrive - University of Leeds\Documents\Programming\phas_vitals\apps\minerva\models.py", line 88, in __str__
    return f"{self.test.name} : {self.user.displayname} {'passed' if self.passed else 'not passed'}"
                                 ^^^^^^^^^^^^^^^^^^^^^
AttributeError: 'Account' object has no attribute 'displayname'
Internal Server Error: /minerva/import_history/
Traceback (most recent call last):
  File "C:\ProgramData\anaconda3\envs\django\Lib\site-packages\django\core\handlers\exception.py", line 55, in inner
    response = get_response(request)
               ^^^^^^^^^^^^^^^^^^^^^
  File "C:\ProgramData\anaconda3\envs\django\Lib\site-packages\django\core\handlers\base.py", line 197, in _get_response
    response = wrapped_callback(request, *callback_args, **callback_kwargs)
               ^^^^^^^^^^^^^^^^^^^^^^^^^^^^^^^^^^^^^^^^^^^^^^^^^^^^^^^^^^^^
  File "C:\ProgramData\anaconda3\envs\django\Lib\site-packages\django\views\generic\base.py", line 104, in view
    return self.dispatch(request, *args, **kwargs)
           ^^^^^^^^^^^^^^^^^^^^^^^^^^^^^^^^^^^^^^^
  File "C:\ProgramData\anaconda3\envs\django\Lib\site-packages\django\contrib\auth\mixins.py", line 135, in dispatch
    return super().dispatch(request, *args, **kwargs)
           ^^^^^^^^^^^^^^^^^^^^^^^^^^^^^^^^^^^^^^^^^^
  File "C:\ProgramData\anaconda3\envs\django\Lib\site-packages\django\views\generic\base.py", line 143, in dispatch
    return handler(request, *args, **kwargs)
           ^^^^^^^^^^^^^^^^^^^^^^^^^^^^^^^^^
  File "C:\Users\gavin\OneDrive - University of Leeds\Documents\Programming\phas_vitals\apps\minerva\views.py", line 127, in post
    return self.form_valid(form)
           ^^^^^^^^^^^^^^^^^^^^^
  File "C:\Users\gavin\OneDrive - University of Leeds\Documents\Programming\phas_vitals\apps\minerva\views.py", line 163, in form_valid
    assert False
AssertionError
Internal Server Error: /minerva/import_history/
Traceback (most recent call last):
  File "C:\ProgramData\anaconda3\envs\django\Lib\site-packages\django\core\handlers\exception.py", line 55, in inner
    response = get_response(request)
               ^^^^^^^^^^^^^^^^^^^^^
  File "C:\ProgramData\anaconda3\envs\django\Lib\site-packages\django\core\handlers\base.py", line 197, in _get_response
    response = wrapped_callback(request, *callback_args, **callback_kwargs)
               ^^^^^^^^^^^^^^^^^^^^^^^^^^^^^^^^^^^^^^^^^^^^^^^^^^^^^^^^^^^^
  File "C:\ProgramData\anaconda3\envs\django\Lib\site-packages\django\views\generic\base.py", line 104, in view
    return self.dispatch(request, *args, **kwargs)
           ^^^^^^^^^^^^^^^^^^^^^^^^^^^^^^^^^^^^^^^
  File "C:\ProgramData\anaconda3\envs\django\Lib\site-packages\django\contrib\auth\mixins.py", line 135, in dispatch
    return super().dispatch(request, *args, **kwargs)
           ^^^^^^^^^^^^^^^^^^^^^^^^^^^^^^^^^^^^^^^^^^
  File "C:\ProgramData\anaconda3\envs\django\Lib\site-packages\django\views\generic\base.py", line 143, in dispatch
    return handler(request, *args, **kwargs)
           ^^^^^^^^^^^^^^^^^^^^^^^^^^^^^^^^^
  File "C:\Users\gavin\OneDrive - University of Leeds\Documents\Programming\phas_vitals\apps\minerva\views.py", line 127, in post
    return self.form_valid(form)
           ^^^^^^^^^^^^^^^^^^^^^
  File "C:\Users\gavin\OneDrive - University of Leeds\Documents\Programming\phas_vitals\apps\minerva\views.py", line 163, in form_valid
    test_attempt.save()
  File "C:\Users\gavin\OneDrive - University of Leeds\Documents\Programming\phas_vitals\apps\minerva\models.py", line 111, in save
    assert False, self.score
AssertionError: 4.0
Internal Server Error: /minerva/import_history/
Traceback (most recent call last):
  File "C:\ProgramData\anaconda3\envs\django\Lib\site-packages\django\core\handlers\exception.py", line 55, in inner
    response = get_response(request)
               ^^^^^^^^^^^^^^^^^^^^^
  File "C:\ProgramData\anaconda3\envs\django\Lib\site-packages\django\core\handlers\base.py", line 197, in _get_response
    response = wrapped_callback(request, *callback_args, **callback_kwargs)
               ^^^^^^^^^^^^^^^^^^^^^^^^^^^^^^^^^^^^^^^^^^^^^^^^^^^^^^^^^^^^
  File "C:\ProgramData\anaconda3\envs\django\Lib\site-packages\django\views\generic\base.py", line 104, in view
    return self.dispatch(request, *args, **kwargs)
           ^^^^^^^^^^^^^^^^^^^^^^^^^^^^^^^^^^^^^^^
  File "C:\ProgramData\anaconda3\envs\django\Lib\site-packages\django\contrib\auth\mixins.py", line 135, in dispatch
    return super().dispatch(request, *args, **kwargs)
           ^^^^^^^^^^^^^^^^^^^^^^^^^^^^^^^^^^^^^^^^^^
  File "C:\ProgramData\anaconda3\envs\django\Lib\site-packages\django\views\generic\base.py", line 143, in dispatch
    return handler(request, *args, **kwargs)
           ^^^^^^^^^^^^^^^^^^^^^^^^^^^^^^^^^
  File "C:\Users\gavin\OneDrive - University of Leeds\Documents\Programming\phas_vitals\apps\minerva\views.py", line 127, in post
    return self.form_valid(form)
           ^^^^^^^^^^^^^^^^^^^^^
  File "C:\Users\gavin\OneDrive - University of Leeds\Documents\Programming\phas_vitals\apps\minerva\views.py", line 163, in form_valid
    test_attempt.save()
  File "C:\Users\gavin\OneDrive - University of Leeds\Documents\Programming\phas_vitals\apps\minerva\models.py", line 114, in save
    assert False, self.test_entry.__dict__
AssertionError: {'_state': <django.db.models.base.ModelState object at 0x0000019D928624D0>, 'id': 1, 'user_id': 32, 'test_id': '1009185', 'status': '', 'text': None, 'score': None, 'passed': False}
Internal Server Error: /minerva/import_history/
Traceback (most recent call last):
  File "C:\ProgramData\anaconda3\envs\django\Lib\site-packages\django\core\handlers\exception.py", line 55, in inner
    response = get_response(request)
               ^^^^^^^^^^^^^^^^^^^^^
  File "C:\ProgramData\anaconda3\envs\django\Lib\site-packages\django\core\handlers\base.py", line 197, in _get_response
    response = wrapped_callback(request, *callback_args, **callback_kwargs)
               ^^^^^^^^^^^^^^^^^^^^^^^^^^^^^^^^^^^^^^^^^^^^^^^^^^^^^^^^^^^^
  File "C:\ProgramData\anaconda3\envs\django\Lib\site-packages\django\views\generic\base.py", line 104, in view
    return self.dispatch(request, *args, **kwargs)
           ^^^^^^^^^^^^^^^^^^^^^^^^^^^^^^^^^^^^^^^
  File "C:\ProgramData\anaconda3\envs\django\Lib\site-packages\django\contrib\auth\mixins.py", line 135, in dispatch
    return super().dispatch(request, *args, **kwargs)
           ^^^^^^^^^^^^^^^^^^^^^^^^^^^^^^^^^^^^^^^^^^
  File "C:\ProgramData\anaconda3\envs\django\Lib\site-packages\django\views\generic\base.py", line 143, in dispatch
    return handler(request, *args, **kwargs)
           ^^^^^^^^^^^^^^^^^^^^^^^^^^^^^^^^^
  File "C:\Users\gavin\OneDrive - University of Leeds\Documents\Programming\phas_vitals\apps\minerva\views.py", line 127, in post
    return self.form_valid(form)
           ^^^^^^^^^^^^^^^^^^^^^
  File "C:\Users\gavin\OneDrive - University of Leeds\Documents\Programming\phas_vitals\apps\minerva\views.py", line 163, in form_valid
    test_attempt.save()
  File "C:\Users\gavin\OneDrive - University of Leeds\Documents\Programming\phas_vitals\apps\minerva\models.py", line 114, in save
    self.test_entry.save()
  File "C:\Users\gavin\OneDrive - University of Leeds\Documents\Programming\phas_vitals\apps\minerva\models.py", line 86, in save
    assert False
AssertionError
Internal Server Error: /minerva/import_history/
Traceback (most recent call last):
  File "C:\ProgramData\anaconda3\envs\django\Lib\site-packages\django\core\handlers\exception.py", line 55, in inner
    response = get_response(request)
               ^^^^^^^^^^^^^^^^^^^^^
  File "C:\ProgramData\anaconda3\envs\django\Lib\site-packages\django\core\handlers\base.py", line 197, in _get_response
    response = wrapped_callback(request, *callback_args, **callback_kwargs)
               ^^^^^^^^^^^^^^^^^^^^^^^^^^^^^^^^^^^^^^^^^^^^^^^^^^^^^^^^^^^^
  File "C:\ProgramData\anaconda3\envs\django\Lib\site-packages\django\views\generic\base.py", line 104, in view
    return self.dispatch(request, *args, **kwargs)
           ^^^^^^^^^^^^^^^^^^^^^^^^^^^^^^^^^^^^^^^
  File "C:\ProgramData\anaconda3\envs\django\Lib\site-packages\django\contrib\auth\mixins.py", line 135, in dispatch
    return super().dispatch(request, *args, **kwargs)
           ^^^^^^^^^^^^^^^^^^^^^^^^^^^^^^^^^^^^^^^^^^
  File "C:\ProgramData\anaconda3\envs\django\Lib\site-packages\django\views\generic\base.py", line 143, in dispatch
    return handler(request, *args, **kwargs)
           ^^^^^^^^^^^^^^^^^^^^^^^^^^^^^^^^^
  File "C:\Users\gavin\OneDrive - University of Leeds\Documents\Programming\phas_vitals\apps\minerva\views.py", line 127, in post
    return self.form_valid(form)
           ^^^^^^^^^^^^^^^^^^^^^
  File "C:\Users\gavin\OneDrive - University of Leeds\Documents\Programming\phas_vitals\apps\minerva\views.py", line 163, in form_valid
    test_attempt.save()
  File "C:\Users\gavin\OneDrive - University of Leeds\Documents\Programming\phas_vitals\apps\minerva\models.py", line 115, in save
    self.test_entry.save()
  File "C:\Users\gavin\OneDrive - University of Leeds\Documents\Programming\phas_vitals\apps\minerva\models.py", line 87, in save
    assert False
AssertionError
Internal Server Error: /minerva/import_history/
Traceback (most recent call last):
  File "C:\ProgramData\anaconda3\envs\django\Lib\site-packages\django\core\handlers\exception.py", line 55, in inner
    response = get_response(request)
               ^^^^^^^^^^^^^^^^^^^^^
  File "C:\ProgramData\anaconda3\envs\django\Lib\site-packages\django\core\handlers\base.py", line 197, in _get_response
    response = wrapped_callback(request, *callback_args, **callback_kwargs)
               ^^^^^^^^^^^^^^^^^^^^^^^^^^^^^^^^^^^^^^^^^^^^^^^^^^^^^^^^^^^^
  File "C:\ProgramData\anaconda3\envs\django\Lib\site-packages\django\views\generic\base.py", line 104, in view
    return self.dispatch(request, *args, **kwargs)
           ^^^^^^^^^^^^^^^^^^^^^^^^^^^^^^^^^^^^^^^
  File "C:\ProgramData\anaconda3\envs\django\Lib\site-packages\django\contrib\auth\mixins.py", line 135, in dispatch
    return super().dispatch(request, *args, **kwargs)
           ^^^^^^^^^^^^^^^^^^^^^^^^^^^^^^^^^^^^^^^^^^
  File "C:\ProgramData\anaconda3\envs\django\Lib\site-packages\django\views\generic\base.py", line 143, in dispatch
    return handler(request, *args, **kwargs)
           ^^^^^^^^^^^^^^^^^^^^^^^^^^^^^^^^^
  File "C:\Users\gavin\OneDrive - University of Leeds\Documents\Programming\phas_vitals\apps\minerva\views.py", line 127, in post
    return self.form_valid(form)
           ^^^^^^^^^^^^^^^^^^^^^
  File "C:\Users\gavin\OneDrive - University of Leeds\Documents\Programming\phas_vitals\apps\minerva\views.py", line 163, in form_valid
    test_attempt.save()
  File "C:\Users\gavin\OneDrive - University of Leeds\Documents\Programming\phas_vitals\apps\minerva\models.py", line 115, in save
    self.test_entry.save()
  File "C:\Users\gavin\OneDrive - University of Leeds\Documents\Programming\phas_vitals\apps\minerva\models.py", line 81, in save
    numerically_passed = self.score >= self.test.passing_score
                         ^^^^^^^^^^^^^^^^^^^^^^^^^^^^^^^^^^^^^
TypeError: '>=' not supported between instances of 'dict' and 'float'
Internal Server Error: /minerva/import_history/
Traceback (most recent call last):
  File "C:\ProgramData\anaconda3\envs\django\Lib\site-packages\django\core\handlers\exception.py", line 55, in inner
    response = get_response(request)
               ^^^^^^^^^^^^^^^^^^^^^
  File "C:\ProgramData\anaconda3\envs\django\Lib\site-packages\django\core\handlers\base.py", line 197, in _get_response
    response = wrapped_callback(request, *callback_args, **callback_kwargs)
               ^^^^^^^^^^^^^^^^^^^^^^^^^^^^^^^^^^^^^^^^^^^^^^^^^^^^^^^^^^^^
  File "C:\ProgramData\anaconda3\envs\django\Lib\site-packages\django\views\generic\base.py", line 104, in view
    return self.dispatch(request, *args, **kwargs)
           ^^^^^^^^^^^^^^^^^^^^^^^^^^^^^^^^^^^^^^^
  File "C:\ProgramData\anaconda3\envs\django\Lib\site-packages\django\contrib\auth\mixins.py", line 135, in dispatch
    return super().dispatch(request, *args, **kwargs)
           ^^^^^^^^^^^^^^^^^^^^^^^^^^^^^^^^^^^^^^^^^^
  File "C:\ProgramData\anaconda3\envs\django\Lib\site-packages\django\views\generic\base.py", line 143, in dispatch
    return handler(request, *args, **kwargs)
           ^^^^^^^^^^^^^^^^^^^^^^^^^^^^^^^^^
  File "C:\Users\gavin\OneDrive - University of Leeds\Documents\Programming\phas_vitals\apps\minerva\views.py", line 127, in post
    return self.form_valid(form)
           ^^^^^^^^^^^^^^^^^^^^^
  File "C:\Users\gavin\OneDrive - University of Leeds\Documents\Programming\phas_vitals\apps\minerva\views.py", line 163, in form_valid
    test_attempt.save()
  File "C:\Users\gavin\OneDrive - University of Leeds\Documents\Programming\phas_vitals\apps\minerva\models.py", line 115, in save
    self.test_entry.save()
  File "C:\Users\gavin\OneDrive - University of Leeds\Documents\Programming\phas_vitals\apps\minerva\models.py", line 77, in save
    best_score = self.attempts.aggregate(models.Max("score", default=0))["score_max"]
                 ~~~~~~~~~~~~~~~~~~~~~~~~~~~~~~~~~~~~~~~~~~~~~~~~~~~~~~~^^^^^^^^^^^^^
KeyError: 'score_max'
Internal Server Error: /minerva/import_history/
Traceback (most recent call last):
  File "C:\ProgramData\anaconda3\envs\django\Lib\site-packages\django\core\handlers\exception.py", line 55, in inner
    response = get_response(request)
               ^^^^^^^^^^^^^^^^^^^^^
  File "C:\ProgramData\anaconda3\envs\django\Lib\site-packages\django\core\handlers\base.py", line 197, in _get_response
    response = wrapped_callback(request, *callback_args, **callback_kwargs)
               ^^^^^^^^^^^^^^^^^^^^^^^^^^^^^^^^^^^^^^^^^^^^^^^^^^^^^^^^^^^^
  File "C:\ProgramData\anaconda3\envs\django\Lib\site-packages\django\views\generic\base.py", line 104, in view
    return self.dispatch(request, *args, **kwargs)
           ^^^^^^^^^^^^^^^^^^^^^^^^^^^^^^^^^^^^^^^
  File "C:\ProgramData\anaconda3\envs\django\Lib\site-packages\django\contrib\auth\mixins.py", line 135, in dispatch
    return super().dispatch(request, *args, **kwargs)
           ^^^^^^^^^^^^^^^^^^^^^^^^^^^^^^^^^^^^^^^^^^
  File "C:\ProgramData\anaconda3\envs\django\Lib\site-packages\django\views\generic\base.py", line 143, in dispatch
    return handler(request, *args, **kwargs)
           ^^^^^^^^^^^^^^^^^^^^^^^^^^^^^^^^^
  File "C:\Users\gavin\OneDrive - University of Leeds\Documents\Programming\phas_vitals\apps\minerva\views.py", line 127, in post
    return self.form_valid(form)
           ^^^^^^^^^^^^^^^^^^^^^
  File "C:\Users\gavin\OneDrive - University of Leeds\Documents\Programming\phas_vitals\apps\minerva\views.py", line 163, in form_valid
    test_attempt.save()
  File "C:\Users\gavin\OneDrive - University of Leeds\Documents\Programming\phas_vitals\apps\minerva\models.py", line 115, in save
    self.test_entry.save()
  File "C:\Users\gavin\OneDrive - University of Leeds\Documents\Programming\phas_vitals\apps\minerva\models.py", line 81, in save
    numerically_passed = self.score >= self.test.passing_score
                         ^^^^^^^^^^^^^^^^^^^^^^^^^^^^^^^^^^^^^
TypeError: '>=' not supported between instances of 'dict' and 'float'
Internal Server Error: /minerva/import_history/
Traceback (most recent call last):
  File "C:\ProgramData\anaconda3\envs\django\Lib\site-packages\django\core\handlers\exception.py", line 55, in inner
    response = get_response(request)
               ^^^^^^^^^^^^^^^^^^^^^
  File "C:\ProgramData\anaconda3\envs\django\Lib\site-packages\django\core\handlers\base.py", line 197, in _get_response
    response = wrapped_callback(request, *callback_args, **callback_kwargs)
               ^^^^^^^^^^^^^^^^^^^^^^^^^^^^^^^^^^^^^^^^^^^^^^^^^^^^^^^^^^^^
  File "C:\ProgramData\anaconda3\envs\django\Lib\site-packages\django\views\generic\base.py", line 104, in view
    return self.dispatch(request, *args, **kwargs)
           ^^^^^^^^^^^^^^^^^^^^^^^^^^^^^^^^^^^^^^^
  File "C:\ProgramData\anaconda3\envs\django\Lib\site-packages\django\contrib\auth\mixins.py", line 135, in dispatch
    return super().dispatch(request, *args, **kwargs)
           ^^^^^^^^^^^^^^^^^^^^^^^^^^^^^^^^^^^^^^^^^^
  File "C:\ProgramData\anaconda3\envs\django\Lib\site-packages\django\views\generic\base.py", line 143, in dispatch
    return handler(request, *args, **kwargs)
           ^^^^^^^^^^^^^^^^^^^^^^^^^^^^^^^^^
  File "C:\Users\gavin\OneDrive - University of Leeds\Documents\Programming\phas_vitals\apps\minerva\views.py", line 127, in post
    return self.form_valid(form)
           ^^^^^^^^^^^^^^^^^^^^^
  File "C:\Users\gavin\OneDrive - University of Leeds\Documents\Programming\phas_vitals\apps\minerva\views.py", line 163, in form_valid
    test_attempt.save()
  File "C:\Users\gavin\OneDrive - University of Leeds\Documents\Programming\phas_vitals\apps\minerva\models.py", line 115, in save
    self.test_entry.save()
  File "C:\Users\gavin\OneDrive - University of Leeds\Documents\Programming\phas_vitals\apps\minerva\models.py", line 87, in save
    assert False
AssertionError
Internal Server Error: /minerva/import_history/
Traceback (most recent call last):
  File "C:\ProgramData\anaconda3\envs\django\Lib\site-packages\django\core\handlers\exception.py", line 55, in inner
    response = get_response(request)
               ^^^^^^^^^^^^^^^^^^^^^
  File "C:\ProgramData\anaconda3\envs\django\Lib\site-packages\django\core\handlers\base.py", line 197, in _get_response
    response = wrapped_callback(request, *callback_args, **callback_kwargs)
               ^^^^^^^^^^^^^^^^^^^^^^^^^^^^^^^^^^^^^^^^^^^^^^^^^^^^^^^^^^^^
  File "C:\ProgramData\anaconda3\envs\django\Lib\site-packages\django\views\generic\base.py", line 104, in view
    return self.dispatch(request, *args, **kwargs)
           ^^^^^^^^^^^^^^^^^^^^^^^^^^^^^^^^^^^^^^^
  File "C:\ProgramData\anaconda3\envs\django\Lib\site-packages\django\contrib\auth\mixins.py", line 135, in dispatch
    return super().dispatch(request, *args, **kwargs)
           ^^^^^^^^^^^^^^^^^^^^^^^^^^^^^^^^^^^^^^^^^^
  File "C:\ProgramData\anaconda3\envs\django\Lib\site-packages\django\views\generic\base.py", line 143, in dispatch
    return handler(request, *args, **kwargs)
           ^^^^^^^^^^^^^^^^^^^^^^^^^^^^^^^^^
  File "C:\Users\gavin\OneDrive - University of Leeds\Documents\Programming\phas_vitals\apps\minerva\views.py", line 131, in post
    return self.form_valid(form)
           ^^^^^^^^^^^^^^^^^^^^^
  File "C:\Users\gavin\OneDrive - University of Leeds\Documents\Programming\phas_vitals\apps\minerva\views.py", line 141, in form_valid
    df["AttemptDate"] = pd.to_datetime(df["Attempt Activity"]).tz_localize(settings.TIME_ZONE)
                        ^^^^^^^^^^^^^^^^^^^^^^^^^^^^^^^^^^^^^^^^^^^^^^^^^^^^^^^^^^^^^^^^^^^^^^
  File "C:\ProgramData\anaconda3\envs\django\Lib\site-packages\pandas\core\generic.py", line 11719, in tz_localize
    ax = _tz_localize(ax, tz, ambiguous, nonexistent)
         ^^^^^^^^^^^^^^^^^^^^^^^^^^^^^^^^^^^^^^^^^^^^
  File "C:\ProgramData\anaconda3\envs\django\Lib\site-packages\pandas\core\generic.py", line 11702, in _tz_localize
    raise TypeError(
TypeError: index is not a valid DatetimeIndex or PeriodIndex
Internal Server Error: /minerva/import_history/
Traceback (most recent call last):
  File "C:\ProgramData\anaconda3\envs\django\Lib\site-packages\django\core\handlers\exception.py", line 55, in inner
    response = get_response(request)
               ^^^^^^^^^^^^^^^^^^^^^
  File "C:\ProgramData\anaconda3\envs\django\Lib\site-packages\django\core\handlers\base.py", line 197, in _get_response
    response = wrapped_callback(request, *callback_args, **callback_kwargs)
               ^^^^^^^^^^^^^^^^^^^^^^^^^^^^^^^^^^^^^^^^^^^^^^^^^^^^^^^^^^^^
  File "C:\ProgramData\anaconda3\envs\django\Lib\site-packages\django\views\generic\base.py", line 104, in view
    return self.dispatch(request, *args, **kwargs)
           ^^^^^^^^^^^^^^^^^^^^^^^^^^^^^^^^^^^^^^^
  File "C:\ProgramData\anaconda3\envs\django\Lib\site-packages\django\contrib\auth\mixins.py", line 135, in dispatch
    return super().dispatch(request, *args, **kwargs)
           ^^^^^^^^^^^^^^^^^^^^^^^^^^^^^^^^^^^^^^^^^^
  File "C:\ProgramData\anaconda3\envs\django\Lib\site-packages\django\views\generic\base.py", line 143, in dispatch
    return handler(request, *args, **kwargs)
           ^^^^^^^^^^^^^^^^^^^^^^^^^^^^^^^^^
  File "C:\Users\gavin\OneDrive - University of Leeds\Documents\Programming\phas_vitals\apps\minerva\views.py", line 131, in post
    return self.form_valid(form)
           ^^^^^^^^^^^^^^^^^^^^^
  File "C:\Users\gavin\OneDrive - University of Leeds\Documents\Programming\phas_vitals\apps\minerva\views.py", line 142, in form_valid
    df.AttemptDate.tz_localize(settings.TIME_ZONE)
  File "C:\ProgramData\anaconda3\envs\django\Lib\site-packages\pandas\core\generic.py", line 11719, in tz_localize
    ax = _tz_localize(ax, tz, ambiguous, nonexistent)
         ^^^^^^^^^^^^^^^^^^^^^^^^^^^^^^^^^^^^^^^^^^^^
  File "C:\ProgramData\anaconda3\envs\django\Lib\site-packages\pandas\core\generic.py", line 11702, in _tz_localize
    raise TypeError(
TypeError: index is not a valid DatetimeIndex or PeriodIndex
Internal Server Error: /minerva/import_history/
Traceback (most recent call last):
  File "C:\ProgramData\anaconda3\envs\django\Lib\site-packages\django\core\handlers\exception.py", line 55, in inner
    response = get_response(request)
               ^^^^^^^^^^^^^^^^^^^^^
  File "C:\ProgramData\anaconda3\envs\django\Lib\site-packages\django\core\handlers\base.py", line 197, in _get_response
    response = wrapped_callback(request, *callback_args, **callback_kwargs)
               ^^^^^^^^^^^^^^^^^^^^^^^^^^^^^^^^^^^^^^^^^^^^^^^^^^^^^^^^^^^^
  File "C:\ProgramData\anaconda3\envs\django\Lib\site-packages\django\views\generic\base.py", line 104, in view
    return self.dispatch(request, *args, **kwargs)
           ^^^^^^^^^^^^^^^^^^^^^^^^^^^^^^^^^^^^^^^
  File "C:\ProgramData\anaconda3\envs\django\Lib\site-packages\django\contrib\auth\mixins.py", line 135, in dispatch
    return super().dispatch(request, *args, **kwargs)
           ^^^^^^^^^^^^^^^^^^^^^^^^^^^^^^^^^^^^^^^^^^
  File "C:\ProgramData\anaconda3\envs\django\Lib\site-packages\django\views\generic\base.py", line 143, in dispatch
    return handler(request, *args, **kwargs)
           ^^^^^^^^^^^^^^^^^^^^^^^^^^^^^^^^^
  File "C:\Users\gavin\OneDrive - University of Leeds\Documents\Programming\phas_vitals\apps\minerva\views.py", line 131, in post
    return self.form_valid(form)
           ^^^^^^^^^^^^^^^^^^^^^
  File "C:\Users\gavin\OneDrive - University of Leeds\Documents\Programming\phas_vitals\apps\minerva\views.py", line 143, in form_valid
    assert False
AssertionError
Internal Server Error: /minerva/import_history/
Traceback (most recent call last):
  File "C:\ProgramData\anaconda3\envs\django\Lib\site-packages\django\db\models\query.py", line 916, in get_or_create
    return self.get(**kwargs), False
           ^^^^^^^^^^^^^^^^^^
  File "C:\ProgramData\anaconda3\envs\django\Lib\site-packages\django\db\models\query.py", line 637, in get
    raise self.model.DoesNotExist(
minerva.models.Test_Score.DoesNotExist: Test_Score matching query does not exist.

During handling of the above exception, another exception occurred:

Traceback (most recent call last):
  File "C:\ProgramData\anaconda3\envs\django\Lib\site-packages\django\core\handlers\exception.py", line 55, in inner
    response = get_response(request)
               ^^^^^^^^^^^^^^^^^^^^^
  File "C:\ProgramData\anaconda3\envs\django\Lib\site-packages\django\core\handlers\base.py", line 197, in _get_response
    response = wrapped_callback(request, *callback_args, **callback_kwargs)
               ^^^^^^^^^^^^^^^^^^^^^^^^^^^^^^^^^^^^^^^^^^^^^^^^^^^^^^^^^^^^
  File "C:\ProgramData\anaconda3\envs\django\Lib\site-packages\django\views\generic\base.py", line 104, in view
    return self.dispatch(request, *args, **kwargs)
           ^^^^^^^^^^^^^^^^^^^^^^^^^^^^^^^^^^^^^^^
  File "C:\ProgramData\anaconda3\envs\django\Lib\site-packages\django\contrib\auth\mixins.py", line 135, in dispatch
    return super().dispatch(request, *args, **kwargs)
           ^^^^^^^^^^^^^^^^^^^^^^^^^^^^^^^^^^^^^^^^^^
  File "C:\ProgramData\anaconda3\envs\django\Lib\site-packages\django\views\generic\base.py", line 143, in dispatch
    return handler(request, *args, **kwargs)
           ^^^^^^^^^^^^^^^^^^^^^^^^^^^^^^^^^
  File "C:\Users\gavin\OneDrive - University of Leeds\Documents\Programming\phas_vitals\apps\minerva\views.py", line 131, in post
    return self.form_valid(form)
           ^^^^^^^^^^^^^^^^^^^^^
  File "C:\Users\gavin\OneDrive - University of Leeds\Documents\Programming\phas_vitals\apps\minerva\views.py", line 155, in form_valid
    test_score, new = Test_Score.objects.get_or_create(user=student, test=test)
                      ^^^^^^^^^^^^^^^^^^^^^^^^^^^^^^^^^^^^^^^^^^^^^^^^^^^^^^^^^
  File "C:\ProgramData\anaconda3\envs\django\Lib\site-packages\django\db\models\manager.py", line 87, in manager_method
    return getattr(self.get_queryset(), name)(*args, **kwargs)
           ^^^^^^^^^^^^^^^^^^^^^^^^^^^^^^^^^^^^^^^^^^^^^^^^^^^
  File "C:\ProgramData\anaconda3\envs\django\Lib\site-packages\django\db\models\query.py", line 923, in get_or_create
    return self.create(**params), True
           ^^^^^^^^^^^^^^^^^^^^^
  File "C:\ProgramData\anaconda3\envs\django\Lib\site-packages\django\db\models\query.py", line 658, in create
    obj.save(force_insert=True, using=self.db)
  File "C:\Users\gavin\OneDrive - University of Leeds\Documents\Programming\phas_vitals\apps\minerva\models.py", line 77, in save
    best_score = self.attempts.aggregate(models.Max("score", default=0)).get('score__max',None)
                 ^^^^^^^^^^^^^^^^^^^^^^^^^^^^^^^^^^^^^^^^^^^^^^^^^^^^^^^
  File "C:\ProgramData\anaconda3\envs\django\Lib\site-packages\django\db\models\manager.py", line 87, in manager_method
    return getattr(self.get_queryset(), name)(*args, **kwargs)
                   ^^^^^^^^^^^^^^^^^^^
  File "C:\ProgramData\anaconda3\envs\django\Lib\site-packages\django\db\models\fields\related_descriptors.py", line 718, in get_queryset
    raise ValueError(
ValueError: 'Test_Score' instance needs to have a primary key value before this relationship can be used.
